Workbook

Sheet 使用教程
D1: 不想看文档版可以看链接 | G1: 终末地计算器变得这么方便了，你居然没用过！！
A3: 汤汤使用教程 | C3: 1 | D3: 从主c角色库或者拐角色库选择角色
C4: 2 | D4: 从c列的某个单元格，值为数值栏开始，将整个数值栏按下ctrl+c复制，如图下
C20: 3 | D20: 点击计算器模板，往下拖到a86单元格，按右键，选择链接复制
C21: 4 | D21: 滚轮往上到超级表，只用编辑技能名称和增益栏（也就是红字列），然后就是自由的出招算伤害了
E34: 你是个合格的汤汤，这么复杂的计算器都能独自掌握
A37: 进阶教学·陈千语都能学会
C39: 5 | D39: 返回主c角色库，调整精锻等级，技能等级 | K39: 只要你保证第三步操作正确，你是链接复制到计算器的
C55: 6 | D55: 调整武器和装备时，要注意到绿色词条有所变化，随着角色面板的词条也有所变化
C79: 7 | D79: 发现武器的珠子对应不上（默认994珠子），直接跳转武器库直接修改数值，再在数值栏的下方buff栏修改武器数值 | P79: 用完之后可以用994武器库直接覆盖，不用一个个还原
D107: 恭喜你,你已经完全掌握了灵活使用计算器了
A113: 管理员都能学会 | D113: 到了这一步，说明你对伤害计算有一定了解了，向zmd高手进军。一起来制作你喜欢的干员吧
C116: 1 | D116: 首先你要对zmd的出伤逻辑有概念，还不清楚的，可以打开计算公式简单学习一下
C117: 2 | D117: 录制单人打罗丹的视频素材，对角色大部分的出伤情况和上拐的个数有参考依据，以及打开网页华法琳wiki
C118: 3 | D118: 复制角色库最下方的干员模板，建议拖动A：A列的最左边列往下拖动复制，直接右键,选择插入复制单元格
C140: 4 | D140: 从左上往右下一次填写，装备栏，角色面板栏，技能倍率栏，的其中蓝色单元格和绿色单元格
D141: 其中装备所带来的主能力值，主能力百分比提升已经自动计算了，无需管理员额外计算。
D142: 加固定攻击力值的词条点击绿色单元格下一格，将公式最后的/100手动删除
C146: 5 | D146: 技能倍率栏，需要你对excel有一定了解，在角色库的最右边放着对应角色的技能倍率，查询华法琳wiki，将倍率一一复制到对应角色，
D147: 再对技能倍率栏的蓝色单元格下一格的公式的第二参数进行修改，一定要是整行的数据，不懂的可以查询之前做好的干员进行查询
C150: 6 | D150: 所有工作准备好了，到了最重要的数值栏的填写了
D151: 首先根据角色面板栏的绿色单元格，来填写角色面板的绿色单元格 | S151: 填写角色面板
D152: 之后填写技能名称和伤害倍率，利用各种sum和product公式结合技能倍率栏填写相关倍率
S153: 填写技能名称
D154: 技能名称和拐名称填写顺序，普攻(5段的自动填写了，4段的需要手动修改） ->战技 ->连携 -> 大招 -> 天赋的额外倍率 -> 潜能 -> 套装 -> 武器
S155: 填写buff名称
D156: 例如伊冯的大招持续7s，加尾端伤害持续8.3s，超过了杰哥大招的覆盖，且大招转身前在叠层暴击暴伤，所以要分段描述技能
D157: 也就是说技能分的越多段，buff就更好填写，伤害计算就越精准
D158: 技能描述尽可能是全中文，拐名称最好附带触发条件
C164: 7 | D164: 使用计算器时，建议新建一个工作表叫做****队伍，将队伍4人所有信息复制粘贴。再复制出一个计算器
C167: 8 | D167: 有bug可以找版本信息的作者投诉交流。由于最后的总伤计算与管理员对终末地的buff与技能的理解，我不敢保证最后的结果一定是对的。
D168: 一切以实际游戏为准。有时候不一定是计算器公式出错了。
D169: 至于为什么大多数时候单次伤害和计算器不一致，因为yj把装备词条的两位小数点后面的数字隐藏掉了。也就是说buff上的越多误差就越大
D170: 作者不会解包数据，能力有限。
C173: 9 | D173: 完结撒花！！！
A177: 干员模板
B178: 干员
B179: 装备栏 | C179: 武器 | D179: 护甲 | E179: 护手 | F179: 配件1 | G179: 配件2 | H179: 套装效果 | I179: 潜能 | R179: excel | S179: 看华法林wiki | AE179: 普攻
B180: 名称 | H180: =IF(COUNTIF(E180:G180,LEFT(D180,2)&"*")>=2,LEFT(D180,2), IF(COUNTIF(F180:G180,LEFT(E180,2)&"*")=2,LEFT(E180,2), "")) | I180: 0 | R180: 复制模板 | AE180: 普攻第一段倍率 | AF180: 0.23 | AG180: 0.25 | AH180: 0.27 | AI180: 0.29 | AJ180: 0.32 | AK180: 0.34 | AL180: 0.36 | AM180: 0.39 | AN180: 0.41 | AO180: 0.44 | AP180: 0.47 | AQ180: 0.51
B181: 等级 | D181: 3 | E181: 3 | F181: 3 | G181: 3 | R181: 改名字 | AE181: 普攻第二段倍率 | AF181: 0.25 | AG181: 0.28 | AH181: 0.3 | AI181: 0.33 | AJ181: 0.35 | AK181: 0.38 | AL181: 0.4 | AM181: 0.43 | AN181: 0.45 | AO181: 0.48 | AP181: 0.52 | AQ181: 0.56
...

Sheet 计算公式参考
B2: 详细机制请看 | D2: https://shimo.im/docs/htrCFTqetCEpUXpM
B4: 常规伤害= 基础伤害区* 暴击区* 伤害加成区* 伤害减免区* 易伤区*增幅区* 虚弱区* 庇护区* 脆弱区* 防御区* 失衡易伤区* 抗性区* 特殊乘区* 非主控减伤区* 连击增伤区
B6: 异常伤害= 基础伤害区* 暴击区* 伤害加成区* 伤害减免区* 易伤区* 增幅区* 虚弱区* 庇护区* 脆弱区* 防御区* 失衡易伤区* 抗性区* 特殊乘区* 等级系数区* 源石技艺强度区
B8: 常规伤害详解
B9: 伤害乘区 | C9: 基础伤害区 | D9: 伤害加成区 | E9: 暴击区 | F9: 伤害减免区 | G9: 增幅区 | H9: 虚弱区 | I9: 庇护区 | J9: 脆弱区 | K9: 易伤区 | L9: 防御区 | M9: 失衡易伤区 | N9: 抗性区 | O9: 非主控减伤区 | P9: 连击增伤区 | Q9: 特殊乘区
B10: 对敌方 | C10: 攻击力*伤害倍率+基础伤害提升值 | D10: 1+伤害类型+技能类型+失衡+其他 | E10: 1+暴击率*暴击伤害 | F10: 武器本效果 | G10: 增幅效果 | J10: 脆弱效果 | K10: 受到伤害 | L10: 0.5 | M10: 1.3 | N10: 1-抗性/100+无视抗性/100 | P10: 连击增伤 | Q10: 怪物特殊机制
B11: 对友方 | H11: 卡契尔的终结技 | I11: 昼雪和卡契尔的战技 | L11: =140/240 -> 0.58333333 | M11: 1 | N11: 1/(0.001*敏捷/智识+1）
B13: 纯伤害计算
B14: 伤害乘区 | C14: 基础伤害区 | D14: 伤害加成区 | E14: 增幅区 | F14: 脆弱区 | G14: 易伤区 | H14: 连击增伤区 | I14: 抗性区 | J14: 防御区 | K14: 失衡易伤区 | L14: 暴击区 | M14: 伤害减免区 | N14: 特殊乘区
B15: 对敌方 | C15: 攻击力*伤害倍率+基础伤害提升值 | D15: 1+伤害类型+技能类型+失衡+其他 | E15: 增幅效果 | F15: 脆弱效果 | G15: 受到伤害 | H15: 连击增伤 | I15: 1-抗性/100+无视抗性/100 | J15: 0.5 | K15: 1.3 | L15: 1+暴击率*暴击伤害 | M15: 武器副本效果 | N15: 怪物特殊机制
I16: 1/(0.001*敏捷/智识+1） | J16: =140/240 -> 0.58333333 | K16: 1
B18: 常规伤害看着有这么多乘区。实际上我们可以分为三个部分。一个是主c面板区，一个是拐区，一个是固定区
B19: 主c面板区：基础伤害区*伤害加成区。实际上就是面板攻击力*技能倍率*伤害加成
B20: 拐区：易伤区*增幅区*脆弱区*抗性区*连击增伤区。这是先有大多角色可以改变的乘区
B21: 固定区：防御区*暴击区*失衡易伤区*特殊副本乘区
B22: 与伤害无关区：伤害减免区*虚弱区*庇护区*非主控减伤区
B26: 异常伤害详解
B27: 异常伤害 | C27: 异常等级 | D27: 等级系数区 | E27: 源石技艺强度区
B28: 法术 | D28: 1+(触发者等级-1)/196 | E28: 1+源石技艺强度/100
B29: 物理 | D29: 1+(触发者等级-1)/392
B31: 「法术异常和法术爆发」
B33: [法术附着]：一些技能会对敌人施加[法术附着]，根据敌人身上已有的[法术附着]和本次施加的[法术附着]会触发对应的[法术异常]和[法术爆发]效果。
B34: [导电]：对处于其他[法术附着]状态下的敌人施加电磁附着时，会消耗所有的[法术附着]层数触发[导电]，根据异常等级，造成电磁伤害，敌人受到的法术伤害提高 12%/16%/20%/24%，[导电]状态初始持续时间为 12/18/24/30 秒。
B35: [腐蚀]：对处于其他[法术附着]状态下的敌人施加自然附着时，会消耗所有的[法术附着]层数触发[腐蚀]，根据异常等级，造成自然伤害，敌人初始降低 3.6/4.8/6/7.2 点全属性抗性，每秒降低 0.84/1.12/1.4/1.68 点全属性抗性，至多降低 12/16/20/24 点全属性抗性，[腐蚀]状态初始持续时间为 15 秒。如果刷新[腐蚀]状态，会维持之前的抗性下降。
B36: [燃烧]：对处于其他[法术附着]状态下的敌人施加灼热附着时，会消耗所有的[法术附着]层数触发[燃烧]，根据异常等级，造成灼热伤害，敌人每秒受到一次持续伤害，[燃烧]状态初始持续时间为 10 秒。
B37: [冻结]：对处于其他[法术附着]状态下的敌人施加寒冷附着时，会消耗所有的[法术附着]层数触发[冻结]，根据异常等级，造成寒冷伤害，并使弱小的敌人无法行动，[冻结]状态初始持续时间依次为 6/7/8/9 秒。
B38: [碎冰]：对处于[冻结]状态下的敌人施加[破防]或物理异常时会触发[碎冰]，消耗敌人的[冻结]状态，并造成大量物理伤害。
B39: [法术爆发]：对处于[法术附着]状态下的敌人施加相同属性[法术附着]时，会叠加一次对应属性[法术附着]（最多为 4 层），并对敌人造成一次对应属性伤害。
B41: [导电]、[腐蚀]、[燃烧]和[冻结]的初始伤害倍率= 80%* (1+ 异常等级)
B42: [燃烧]的持续伤害倍率= 12%* (1+ 异常等级)
B43: [碎冰]的伤害倍率= 120%* (1+ 异常等级)
B44: 任意[法术爆发]的伤害倍率= 160%
... B57: [猛击]的伤害倍率= 150%* (1+ 异常等级)

Sheet 武器库
B1: 默认满级0潜能,满珠子
B2: 名称 | C2: 词条1 | D2: 词条2 | E2: 词条3 | F2: 额外词条
A3: 大剑 | B3: 赫拉芬格 | C3: 力量156 | D3: 攻击力39 | E3: 全技伤32.0 | F3: 装备者通过战技施加寒冷附着时，获得寒冷伤害+16.0%，持续15秒。装备者对寒冷附着的敌人造成连携技伤害时，获得寒冷伤害+32.0%，持续15秒。
A9: 施术单元 | B9: 爆破单元 | C9: 主能力值132 | D9: 源石技艺78 | E9: 副能力16.0 | F9: 装备者造成法术爆发时，使目标敌人受到的法术伤害+14.4%，持续15秒。
B10: 沧溟星梦 | C10: 智识156 | D10: 治疗效率46.4 | E10: 副能力25.6 | F10: 装备者消耗腐蚀后，使目标敌人受到的法术伤害+16.0%，持续25秒。
B11: 悼亡诗 | C11: 智识105 | D11: 攻击力31.2 | E11: 最大生命值+16.0%。 | F11: 装备者施放终结技时，和自身属性不同的干员获得攻击力12.8，持续20秒。
B12: 使命必达 | C12: 意志+156 | D12: 充能46.4 | E12: 自然伤害+25.6 | F12: 装备者通过自身连携技造成击飞后，全队造成的法术伤害+19.2%，持续15秒。每有一个被击飞的敌人，全队造成的法术伤害额外+5.6%，最多+16.8%。
B13: 骑士精神 | C13: 意志+156 | D13: 最大生命值+78.0 | E13: 治疗效率+16.0 | F13: 装备者通过自身技能治疗后，全队攻击力+14.4%，持续15秒
B14: 孤舟 | C14: 意志+156 | D14: 攻击力+39.0 | E14: 电磁伤害+44.8 | F14: 装备者通过战技消耗法术异常时，战技造成的电磁+伤害+56.0%，持续20秒。该效果最多叠加2层。装备者施放终结技后，战技造成的电磁+伤害+112.0%，持续25秒。
B15: 雾中微光 | C15: 意志+156 | D15: 电磁伤害+43.3 | E15: 攻击力+11.2 | F15: 装备者获得电磁增幅时，电磁伤害+8.8%，持续30秒。
B16: 迷失荒野 | C16: 智识+124 | D16: 电磁伤害+34.7 | E16: 源石技艺+16 | F16: 装备者施加导电时，全队获得物理和电磁伤害+12.8%，持续15秒。
B17: 吉米尼12 | C17: 主能力值+10 | D17: 攻击力值+12
A22: 手铳 | B22: 落草 | C22: 敏捷156 | D22: 攻击力39 | E22: 寒冷伤害25.6 | F22: 装备者通过战技或终结技施加寒冷附着时，获得寒冷伤害+32.0%，持续20秒。装备者通过战技或终结技施加法术脆弱时，使目标敌人受到的法术伤害+9.6%，持续20秒。
B23: 望乡 | C23: 敏捷156 | D23: 寒冷伤害+43.3 | E23: 攻击力11.2 | F23: 装备者施放连携技后，战技造成的寒冷和自然伤害+12.8%，持续20秒。
B24: 艺术暴君 | C24: 智识+156 | D24: 暴击+19.5 | E24: 寒冷伤害+25.6 | F24: 装备者的战技或连携技造成暴击伤害后，寒冷+伤害+22.4%，持续30秒
B25: 楔子 | C25: 主能力值+132 | D25: 暴击+19.5 | E25: 法术伤害+19.2 | F25: 装备者施放战技时，获得法术伤害+12.8%，持续15秒。装备者通过自身战技施加法术异常时，获得法术伤害+25.6%，持续15秒
B26: 佩科5 | C26: 主能力值+10 | D26: 攻击力值+12
A31: 单手剑 | B31: 宏愿 | C31: 敏捷+156 | D31: 攻击力+39.0% | E31: 技艺48 | F31: 装备者施加源石结晶或冻结时，20秒内的下次战技或终结技期间，造成的物理伤害+57.6%。
B32: 狼之绯 | C32: 敏捷+156 | D32: 暴击19.5 | E32: 攻击力25.6 | F32: 装备者造成暴击伤害后，获得1层狼血，物理和灼热伤害+1.6%，最多叠加16层。当狼血叠加至16层后，物理和灼热伤害额外+38.4%，持续20秒。持续时间结束后，清空所有狼血叠加层数。
B33: 光荣记忆 | C33: 敏捷+156 | D33: 暴击19.5 | E33: 攻击力12.6 | F33: 装备者通过技能施加破防时，30秒内的下次终结技期间造成的伤害+21.6%。
B34: 显赫声名 | C34: 主能力值+132 | D34: 物伤43.3 | E34: 攻击力+16.0 | F34: 装备者消耗破防层数后，自身攻击力+[7.0%+3.5%×消耗层数]，小队内其他干员获得一半的效果，持续20秒。
B35: 熔铸火焰 | C35: 智识+156 | D35: 攻击力+39.0 | E35: 灼热伤害+25.6 | F35: 装备者施放终结技时，获得普通攻击伤害+120.0%，持续20秒
B36: 白夜新星 | C36: 主能力值+132 | D36: 源石技艺+78 | E36: 法术伤害+19.2 | F36: 装备者施加燃烧或导电后，法术+伤害+19.2，源石技艺强度+40，持续15秒。
B37: 热熔切割器 | C37: 意志+156 | D37: 攻击力+39.0 | E37: 攻击力+16.0 | F37: 装备者通过自身技能恢复技力或获得连击状态后，全队攻击力+8.0%，持续20秒
B38: OBJ轻芒 | C38: 敏捷+124 | D38: 攻击力+31.2 | E38: 副能力+8.0 | F38: 装备者通过自身技能恢复技力后，全队造成的灼热和电磁伤害+4.8%，持续20秒。

Sheet 994武器库
B1: 默认满级0潜能,满珠子
B2: 名称 | C2: 词条1 | D2: 词条2 | E2: 词条3 | F2: 额外词条
A3: 大剑 | B3: 赫拉芬格 | C3: 力量156 | D3: 攻击力39 | E3: 全技伤32.0 | F3: 装备者通过战技施加寒冷附着时，获得寒冷伤害+16.0%，持续15秒。装备者对寒冷附着的敌人造成连携技伤害时，获得寒冷伤害+32.0%，持续15秒。
A9: 施术单元 | B9: 爆破单元 | C9: 主能力值132 | D9: 源石技艺78 | E9: 副能力16.0 | F9: 装备者造成法术爆发时，使目标敌人受到的法术伤害+14.4%，持续15秒。
B10: 沧溟星梦 | C10: 智识156 | D10: 治疗效率46.4 | E10: 副能力25.6 | F10: 装备者消耗腐蚀后，使目标敌人受到的法术伤害+16.0%，持续25秒。
B11: 悼亡诗 | C11: 智识105 | D11: 攻击力31.2 | E11: 最大生命值+16.0%。 | F11: 装备者施放终结技时，和自身属性不同的干员获得攻击力12.8，持续20秒。
B12: 使命必达 | C12: 意志+156 | D12: 充能46.4 | E12: 自然伤害+25.6 | F12: 装备者通过自身连携技造成击飞后，全队造成的法术伤害+19.2%，持续15秒。每有一个被击飞的敌人，全队造成的法术伤害额外+5.6%，最多+16.8%。
B13: 骑士精神 | C13: 意志+156 | D13: 最大生命值+78.0 | E13: 治疗效率+16.0 | F13: 装备者通过自身技能治疗后，全队攻击力+14.4%，持续15秒
B14: 孤舟 | C14: 意志+156 | D14: 攻击力+39.0 | E14: 电磁伤害+25.6 | F14: 装备者通过战技消耗法术异常时，战技造成的电磁+伤害+32.0%，持续20秒。该效果最多叠加2层。装备者施放终结技后，战技造成的电磁+伤害+64.0%，持续25秒。
B15: 雾中微光 | C15: 意志+156 | D15: 电磁伤害+43.3 | E15: 攻击力+11.2 | F15: 装备者获得电磁增幅时，电磁伤害+8.8%，持续30秒。
B16: 迷失荒野 | C16: 智识+124 | D16: 电磁伤害+34.7 | E16: 源石技艺+16 | F16: 装备者施加导电时，全队获得物理和电磁伤害+12.8%，持续15秒。
B17: 吉米尼12 | C17: 主能力值+10 | D17: 攻击力值+12
A22: 手铳 | B22: 落草 | C22: 敏捷156 | D22: 攻击力39 | E22: 寒冷伤害25.6 | F22: 装备者通过战技或终结技施加寒冷附着时，获得寒冷伤害+32.0%，持续20秒。装备者通过战技或终结技施加法术脆弱时，使目标敌人受到的法术伤害+9.6%，持续20秒。
B23: 望乡 | C23: 敏捷156 | D23: 寒冷伤害+43.3 | E23: 攻击力11.2 | F23: 装备者施放连携技后，战技造成的寒冷和自然伤害+12.8%，持续20秒。
B24: 艺术暴君 | C24: 智识+156 | D24: 暴击+19.5 | E24: 寒冷伤害+25.6 | F24: 装备者的战技或连携技造成暴击伤害后，寒冷+伤害+22.4%，持续30秒
B25: 楔子 | C25: 主能力值+132 | D25: 暴击+19.5 | E25: 法术伤害+19.2 | F25: 装备者施放战技时，获得法术伤害+12.8%，持续15秒。装备者通过自身战技施加法术异常时，获得法术伤害+25.6%，持续15秒
B26: 佩科5 | C26: 主能力值+10 | D26: 攻击力值+12
A31: 单手剑 | B31: 宏愿 | C31: 敏捷+156 | D31: 攻击力+39.0% | E31: 技艺48 | F31: 装备者施加源石结晶或冻结时，20秒内的下次战技或终结技期间，造成的物理伤害+57.6%。
B32: 狼之绯 | C32: 敏捷+156 | D32: 暴击19.5 | E32: 攻击力25.6 | F32: 装备者造成暴击伤害后，获得1层狼血，物理和灼热伤害+1.6%，最多叠加16层。当狼血叠加至16层后，物理和灼热伤害额外+38.4%，持续20秒。持续时间结束后，清空所有狼血叠加层数。
B33: 光荣记忆 | C33: 敏捷+156 | D33: 暴击19.5 | E33: 攻击力12.6 | F33: 装备者通过技能施加破防时，30秒内的下次终结技期间造成的伤害+21.6%。
B34: 显赫声名 | C34: 主能力值+132 | D34: 物伤43.3 | E34: 攻击力+16.0 | F34: 装备者消耗破防层数后，自身攻击力+[7.0%+3.5%×消耗层数]，小队内其他干员获得一半的效果，持续20秒。
B35: 熔铸火焰 | C35: 智识+156 | D35: 攻击力+39.0 | E35: 灼热伤害+25.6 | F35: 装备者施放终结技时，获得普通攻击伤害+120.0%，持续20秒
B36: 白夜新星 | C36: 主能力值+132 | D36: 源石技艺+78 | E36: 法术伤害+19.2 | F36: 装备者施加燃烧或导电后，法术+伤害+19.2，源石技艺强度+40，持续15秒。
B37: 热熔切割器 | C37: 意志+156 | D37: 攻击力+39.0 | E37: 攻击力+16.0 | F37: 装备者通过自身技能恢复技力或获得连击状态后，全队攻击力+8.0%，持续20秒
B38: OBJ轻芒 | C38: 敏捷+124 | D38: 攻击力+31.2 | E38: 副能力+8.0 | F38: 装备者通过自身技能恢复技力后，全队造成的灼热和电磁伤害+4.8%，持续20秒。

Sheet 拐力角色库
AF6: 1 | AG6: 2 | AH6: 3 | AI6: 4 | AJ6: 5 | AK6: 6 | AL6: 7 | AM6: 8 | AN6: 9 | AO6: M1 | AP6: M2 | AQ6: M3
B7: 小羊
B8: 装备栏 | C8: 武器 | D8: 护甲 | E8: 护手 | F8: 配件1 | G8: 配件2 | H8: 套装效果 | I8: 潜能 | AE8: 战技
B9: 名称 | C9: 沧溟星梦 | D9: 长息装甲 | E9: 长息护手一 | F9: 长息辅助臂 | G9: 动火用测温镜 | H9: =IF(COUNTIF(E9:G9,LEFT(D9,2)&"*")>=2,LEFT(D9,2), IF(COUNTIF(F9:G9,LEFT(E9,2)&"*")=2,LEFT(E9,2), "")) -> 长息 | I9: 0 | AF9: 1 | AG9: 2 | AH9: 3 | AI9: 4 | AJ9: 5 | AK9: 6 | AL9: 7 | AM9: 8 | AN9: 9 | AO9: M1 | AP9: M2 | AQ9: M3
B10: 等级 | D10: 3 | E10: 3 | F10: 3 | G10: 3 | AE10: 伤害倍率 | AF10: 1.42 | AG10: 1.56 | AH10: 1.71 | AI10: 1.85 | AJ10: 1.99 | AK10: 2.13 | AL10: 2.28 | AM10: 2.42 | AN10: 2.56 | AO10: 2.74 | AP10: 2.95 | AQ10: 3.2
B11: 词条1 | C11: =_xlfn.XLOOKUP(C9,武器库!$B:$B,武器库!$C:$C,"") -> 智识156 | D11: =VLOOKUP(D9,护甲库!$A:$M,2+D10*3,FALSE) -> 意志113 | E11: =VLOOKUP(E9,护手库!$A:$M,2+E10*3,FALSE) -> 智识84 | F11: =VLOOKUP(F9,配件库!$A:$M,2+F10*3,FALSE) -> 意志41 | G11: =VLOOKUP(G9,配件库!$A:$M,2+G10*3,FALSE) -> 智识53 | AE11: 失衡值 | AF11: 10 | AG11: 10 | AH11: 10 | AI11: 10 | AJ11: 10 | AK11: 10 | AL11: 10 | AM11: 10 | AN11: 10 | AO11: 10 | AP11: 10 | AQ11: 10
B12: 词条2 | C12: =_xlfn.XLOOKUP(C9,武器库!$B:$B,武器库!$D:$D,"") -> 治疗效率46.4 | D12: =VLOOKUP(D9,护甲库!$A:$M,3+D10*3,FALSE) -> 智识75 | E12: =VLOOKUP(E9,护手库!$A:$M,3+E10*3,FALSE) -> 意志55 | F12: =VLOOKUP(F9,配件库!$A:$M,3+F10*3,FALSE) -> 智识27 | G12: =VLOOKUP(G9,配件库!$A:$M,3+G10*3,FALSE) -> 0 | AE12: 脆弱效果 | AF12: 0.12 | AG12: 0.12 | AH12: 0.12 | AI12: 0.13 | AJ12: 0.13 | AK12: 0.13 | AL12: 0.14 | AM12: 0.14 | AN12: 0.16 | AO12: 0.17 | AP12: 0.18 | AQ12: 0.2
B13: 词条3 | C13: =_xlfn.XLOOKUP(C9,武器库!$B:$B,武器库!$E:$E,"") -> 副能力25.6 | D13: =VLOOKUP(D9,护甲库!$A:$M,4+D10*3,FALSE) -> 技艺26 | E13: =VLOOKUP(E9,护手库!$A:$M,4+E10*3,FALSE) -> 充能26.7 | F13: =VLOOKUP(F9,配件库!$A:$M,4+F10*3,FALSE) -> 充能32.0 | G13: =VLOOKUP(G9,配件库!$A:$M,4+G10*3,FALSE) -> 战技53.8 | AE13: 脆弱持续时间（秒） | AF13: 30 | AG13: 30 | AH13: 30 | AI13: 30 | AJ13: 30 | AK13: 30 | AL13: 30 | AM13: 30 | AN13: 30 | AO13: 30 | AP13: 30 | AQ13: 30
B14: 武器效果 | C14: =_xlfn.XLOOKUP(C9,武器库!$B:$B,武器库!$F:$F,"") -> 装备者消耗腐蚀后，使目标敌人受到的法术伤害+16.0%，持续25秒。
B15: 套装效果 | C15: =VLOOKUP(H9,套装效果库!A:B,2,0) -> 生命值+1000。装备者施加增幅、庇护、脆弱、虚弱后，使其他队友造成的伤害+16%，持续15秒。该效果无法叠加。
C18: 主能力值 | D18: 副能力值 | L18: 普攻 | M18: 战技 | N18: 连携 | O18: 大招
C19: 智识 | D19: 意志 | E19: 副能力 | F19: 技艺 | G19: 战技 | H19: 治疗效率 | K19: 等级 | L19: 0 | M19: M3 | N19: 0 | O19: 0
B20: 角色 | C20: =145+60 -> 205 | D20: 118 | E20: {=SUM(IFERROR( VALUE(MID($C10:$G13, SEARCH(E19, $C10:$G13) + LEN(E19), 10)) * ISNUMBER(SEARCH(E19,$C10:$G13)), 0 ))/100+IFERROR( MID($C15, SEARCH(E19, $C15) + LEN(E19), 2) / 100, 0 )} -> 0.256 | F20: {=SUM(IFERROR( VALUE(MID($C10:$G13, SEARCH(F19, $C10:$G13) + LEN(F19), 10)) * ISNUMBER(SEARCH(F19,$C10:$G13)), 0 ))/100+IFERROR( MID($C15, SEARCH(F19, $C15) + LEN(F19), 2) / 100, 0 )} -> 0.26 | G20: {=SUM(IFERROR( VALUE(MID($C10:$G13, SEARCH(G19, $C10:$G13) + LEN(G19), 10)) * ISNUMBER(SEARCH(G19,$C10:$G13)), 0 ))/100+IFERROR( MID($C15, SEARCH(G19, $C15) + LEN(G19), 2) / 100, 0 )} -> 0.538 | H20: {=SUM(IFERROR( VALUE(MID($C10:$G13, SEARCH(H19, $C10:$G13) + LEN(H19), 10)) * ISNUMBER(SEARCH(H19,$C10:$G13)), 0 ))/100+IFERROR( MID($C15, SEARCH(H19, $C15) + LEN(H19), 2) / 100, 0 )} -> 0.464 | I20: {=SUM(IFERROR( VALUE(MID($C10:$G13, SEARCH(I19, $C10:$G13) + LEN(I19), 10)) * ISNUMBER(SEARCH(I19,$C10:$G13)), 0 ))/100+IFERROR( MID($C15, SEARCH(I19, $C15) + LEN(I19), 2) / 100, 0 )} -> 0.12 | K20: 技能倍率 | L20: {=_xlfn.XLOOKUP(L19,$AE$6:$AQ$6,AE9:AQ15,0,0,1)} -> 0 | M20: {=_xlfn.XLOOKUP(M19,$AE$6:$AQ$6,AE10:AQ13,0,0,1)} -> 3.2 | N20: {=_xlfn.XLOOKUP(N19,$AE$6:$AQ$6,AE40:AQ43,0,0,1)} -> 0 | O20: {=_xlfn.XLOOKUP(O19,$AE$6:$AQ$6,AE48:AQ53,0,0,1)} -> 0
B21: 装备 | C21: {=SUM(IFERROR( VALUE(MID($C10:$G13, FIND(C19, $C10:$G13) + LEN(C19), 10)) * ISNUMBER(FIND(C19, $C10:$G13)), 0 ))+SUM(IFERROR( VALUE(MID($C10:$G13, FIND(C18, $C10:$G13) + LEN(C18), 10)) * ISNUMBER(FIND(C18, $C10:$G13)), 0 ))+IFERROR( MID($C15, SEARCH(C19, $C15) + LEN(C19), 2) / 100, 0 )+IFERROR( MID($C15, SEARCH(C18, $C15) + LEN(C18), 2) / 100, 0 )} -> 395 | D21: {=SUM(IFERROR( VALUE(MID($C10:$G13, FIND(D19, $C10:$G13) + LEN(D19), 10)) * ISNUMBER(FIND(D19, $C10:$G13)), 0 ))+SUM(IFERROR( VALUE(MID($C10:$G13, FIND(D18, $C10:$G13) + LEN(D18), 10)) * ISNUMBER(FIND(D18, $C10:$G13)), 0 ))+IFERROR( MID($C15, SEARCH(D19, $C15) + LEN(D19), 2) / 100, 0 )+IFERROR( MID($C15, SEARCH(D18, $C15) + LEN(D18), 2) / 100, 0 )} -> 209 | M21: 10
B22: 总计 | C22: {=ROUNDUP(SUM(C20:C21)*(1+IF(LEN(TRIM(LEFT(C18,3)))=0, 0, SUMPRODUCT( IFERROR( VALUE(MID($C10:$G13, SEARCH(LEFT(C18,3), $C10:$G13) + 3, 10)) * ISNUMBER(SEARCH(LEFT(C18,3), $C10:$G13)), 0 ) )+IFERROR( MID($C15, SEARCH(C19, $C15) + LEN(C19), 2) / 100, 0 ) )/100),0)} -> 600 | D22: {=ROUNDUP(SUM(D20:D21)*(1+IF(LEN(TRIM(LEFT(D18,3)))=0, 0, SUMPRODUCT( IFERROR( VALUE(MID($C10:$G13, SEARCH(LEFT(D18,3), $C10:$G13) + 3, 10)) * ISNUMBER(SEARCH(LEFT(D18,3), $C10:$G13)), 0 ) )+IFERROR( MID($C15, SEARCH(D19, $C15) + LEN(D19), 2) / 100, 0 ) )/100),0)} -> 411 | M22: 0.2
B23: 能力值加成 | C23: =C22*0.005+D22*0.002 -> 3.822 | M23: 30
C32: 数值栏 | E32: 攻击计算器 | J32: 面板乘区 | N32: 伤害加成 | T32: 拐
B33: 面板 | C33: 技能名称 | D33: buff名称 | E33: 基础攻击力 | F33: 百分比 | G33: 固定数值 | H33: 能力值加成 | I33: 总攻击力 | J33: 倍率 | K33: 暴击率 | L33: 暴击伤害 | M33: 源石技艺 | N33: 基础伤害加成 | O33: 普攻 | P33: 战技 | Q33: 连携 | R33: 大招 | S33: 总伤害加成 | T33: 脆弱 | U33: 增幅 | V33: 易伤 | W33: 抗性 | X33: 连击 | Y33: 失衡易伤 | Z33: 特殊加成
B34: 小羊 | C34: 小羊连携 | D34: N/a
C35: 小羊强化战技 | D35: N/a
B36: 30 | C36: N/a | D36: 小羊强化战技脆弱 | T36: =IF($I$9>0,$L$22+0.08,$L$22) -> 0
B37: 25 | C37: N/a | D37: 小羊强化战技易伤 | V37: =0.14 -> 0.14
B38: 5 | C38: N/a | D38: 小羊连携未满腐蚀 | E38: 抗性 | W38: =0.12*(1+2*$F$20*100/(300+100*$F$20)) -> 0.1391411
B39: 10 | C39: N/a | D39: 小羊连携满腐蚀 | E39: 抗性 | W39: =0.078*(1+2*$F$20*100/(300+100*$F$20)) -> 0.090441718
B40: 15 | C40: N/a | D40: 小羊长息 | N40: =0.16 -> 0.16
B46: 洁哥
B47: 装备栏 | C47: 武器 | D47: 护甲 | E47: 护手 | F47: 配件1 | G47: 配件2 | H47: 套装效果 | I47: 潜能 | AE47: 大招
B48: 名称 | C48: 使命必达 | D48: 点剑轻装甲 | E48: 长息护手一 | F48: 点剑定位信标 | G48: 点剑定位信标 | H48: =IF(COUNTIF(E48:G48,LEFT(D48,2)&"*")>=2,LEFT(D48,2), IF(COUNTIF(F48:G48,LEFT(E48,2)&"*")=2,LEFT(E48,2), "")) -> 点剑 | I48: 0 | AE48: 技能等级 | AF48: 1级 | AG48: 2级 | AH48: 3级 | AI48: 4级 | AJ48: 5级 | AK48: 6级 | AL48: 7级 | AM48: 8级 | AN48: 9级 | AO48: 专1 | AP48: 专2 | AQ48: 专3
B49: 等级 | D49: 3 | E49: 3 | F49: 3 | G49: 3 | AE49: 所需终结技能量 | AF49: 90 | AG49: 90 | AH49: 90 | AI49: 90 | AJ49: 90 | AK49: 90 | AL49: 90 | AM49: 90 | AN49: 90 | AO49: 90 | AP49: 90 | AQ49: 90
B50: 词条1 | C50: =_xlfn.XLOOKUP(C48,武器库!$B:$B,武器库!$C:$C,"") -> 意志+156 | D50: =VLOOKUP(D48,护甲库!$A:$M,2+D49*3,FALSE) -> 力量113 | E50: =VLOOKUP(E48,护手库!$A:$M,2+E49*3,FALSE) -> 智识84 | F50: =VLOOKUP(F48,配件库!$A:$M,2+F49*3,FALSE) -> 力量53 | G50: =VLOOKUP(G48,配件库!$A:$M,2+G49*3,FALSE) -> 力量53 | AE50: 冷却时间 | AF50: 20秒 | AG50: 20秒 | AH50: 20秒 | AI50: 20秒 | AJ50: 20秒 | AK50: 20秒 | AL50: 20秒 | AM50: 20秒 | AN50: 20秒 | AO50: 20秒 | AP50: 20秒 | AQ50: 20秒
B51: 词条2 | C51: =_xlfn.XLOOKUP(C48,武器库!$B:$B,武器库!$D:$D,"") -> 充能46.4 | D51: =VLOOKUP(D48,护甲库!$A:$M,3+D49*3,FALSE) -> 意志75 | E51: =VLOOKUP(E48,护手库!$A:$M,3+E49*3,FALSE) -> 意志55 | F51: =VLOOKUP(F48,配件库!$A:$M,3+F49*3,FALSE) -> 0 | G51: =VLOOKUP(G48,配件库!$A:$M,3+G49*3,FALSE) -> 0 | AE51: 伤害倍率 | AF51: 3.33 | AG51: 3.67 | AH51: 4 | AI51: 4.33 | AJ51: 4.67 | AK51: 5 | AL51: 5.34 | AM51: 5.67 | AN51: 6 | AO51: 6.42 | AP51: 6.92 | AQ51: 7.5
B52: 词条3 | C52: =_xlfn.XLOOKUP(C48,武器库!$B:$B,武器库!$E:$E,"") -> 自然伤害+25.6 | D52: =VLOOKUP(D48,护甲库!$A:$M,4+D49*3,FALSE) -> 充能16.0 | E52: =VLOOKUP(E48,护手库!$A:$M,4+E49*3,FALSE) -> 充能26.7 | F52: =VLOOKUP(F48,配件库!$A:$M,4+F49*3,FALSE) -> 技艺53 | G52: =VLOOKUP(G48,配件库!$A:$M,4+G49*3,FALSE) -> 技艺53 | AE52: 失衡值 | AF52: 20 | AG52: 20 | AH52: 20 | AI52: 20 | AJ52: 20 | AK52: 20 | AL52: 20 | AM52: 20 | AN52: 20 | AO52: 20 | AP52: 20 | AQ52: 20
B53: 武器效果 | C53: =_xlfn.XLOOKUP(C48,武器库!$B:$B,武器库!$F:$F,"") -> 装备者通过自身连携技造成击飞后，全队造成的法术伤害+19.2%，持续15秒。每有一个被击飞的敌人，全队造成的法术伤害额外+5.6%，最多+16.8%。 | AE53: 力场持续时间（秒） | AF53: 5 | AG53: 5 | AH53: 5 | AI53: 5 | AJ53: 5 | AK53: 5 | AL53: 5 | AM53: 5 | AN53: 5 | AO53: 5 | AP53: 5 | AQ53: 5
B54: 套装效果 | C54: =VLOOKUP(H48,套装效果库!A:B,2,0) -> 失衡效率20。当装备者造成物理异常后，额外造成一次250%攻击力的物理伤害[10点失衡值]。该效果每15秒最多触发一次。 | AE54: 缓速效果 | AF54: 0.8 | AG54: 0.8 | AH54: 0.8 | AI54: 0.8 | AJ54: 0.8 | AK54: 0.8 | AL54: 0.8 | AM54: 0.8 | AN54: 0.8 | AO54: 0.8 | AP54: 0.8 | AQ54: 0.8
AE55: 基础法术脆弱效果 | AF55: 0.18 | AG55: 0.18 | AH55: 0.18 | AI55: 0.22 | AJ55: 0.22 | AK55: 0.22 | AL55: 0.26 | AM55: 0.26 | AN55: 0.26 | AO55: 0.3 | AP55: 0.3 | AQ55: 0.3
AE56: 每层破防提升法术脆弱 | AF56: 0.018 | AG56: 0.018 | AH56: 0.018 | AI56: 0.022 | AJ56: 0.022 | AK56: 0.022 | AL56: 0.026 | AM56: 0.026 | AN56: 0.026 | AO56: 0.03 | AP56: 0.03 | AQ56: 0.03
C57: 主能力值 | D57: 副能力值 | L57: 普攻 | M57: 战技 | N57: 连携 | O57: 大招
C58: 意志 | D58: 智识 | E58: 充能 | F58: 技艺 | G58: 自然伤害 | K58: 等级 | L58: 0 | M58: 0 | N58: 0 | O58: M3
B59: 角色 | C59: =154+40 -> 194 | D59: =114 -> 114 | E59: {=SUM(IFERROR( VALUE(MID($C49:$G52, SEARCH(E58, $C49:$G52) + LEN(E58), 10)) * ISNUMBER(SEARCH(E58,$C49:$G52)), 0 ))/100+IFERROR( MID($C54, SEARCH(E58, $C54) + LEN(E58), 2) / 100, 0 )} -> 0.891 | F59: {=SUM(IFERROR( VALUE(MID($C49:$G52, SEARCH(F58, $C49:$G52) + LEN(F58), 10)) * ISNUMBER(SEARCH(F58,$C49:$G52)), 0 ))/100+IFERROR( MID($C54, SEARCH(F58, $C54) + LEN(F58), 2) / 100, 0 )} -> 1.06 | G59: {=SUM(IFERROR( VALUE(MID($C49:$G52, SEARCH(G58, $C49:$G52) + LEN(G58), 10)) * ISNUMBER(SEARCH(G58,$C49:$G52)), 0 ))/100+IFERROR( MID($C54, SEARCH(G58, $C54) + LEN(G58), 2) / 100, 0 )} -> 0.256 | H59: {=SUM(IFERROR( VALUE(MID($C49:$G52, SEARCH(H58, $C49:$G52) + LEN(H58), 10)) * ISNUMBER(SEARCH(H58,$C49:$G52)), 0 ))/100+IFERROR( MID($C54, SEARCH(H58, $C54) + LEN(H58), 2) / 100, 0 )} -> 0.12 | I59: {=SUM(IFERROR( VALUE(MID($C49:$G52, SEARCH(I58, $C49:$G52) + LEN(I58), 10)) * ISNUMBER(SEARCH(I58,$C49:$G52)), 0 ))/100+IFERROR( MID($C54, SEARCH(I58, $C54) + LEN(I58), 2) / 100, 0 )} -> 0.12 | K59: 技能倍率 | L59: {=_xlfn.XLOOKUP(L58,$AE$6:$AQ$6,AE48:AQ54,0,0,1)} -> 0 | M59: {=_xlfn.XLOOKUP(M58,$AE$6:$AQ$6,AE60:AQ67,0,0,1)} -> 0 | N59: {=_xlfn.XLOOKUP(N58,$AE$6:$AQ$6,AE72:AQ75,0,0,1)} -> 0 | O59: {=_xlfn.XLOOKUP(O58,$AE$6:$AQ$6,AE49:AQ56,0,0,1)} -> 90
B60: 装备 | C60: {=SUM(IFERROR( VALUE(MID($C49:$G52, FIND(C58, $C49:$G52) + LEN(C58), 10)) * ISNUMBER(FIND(C58, $C49:$G52)), 0 ))+SUM(IFERROR( VALUE(MID($C49:$G52, FIND(C57, $C49:$G52) + LEN(C57), 10)) * ISNUMBER(FIND(C57, $C49:$G52)), 0 ))+IFERROR( MID($C54, SEARCH(C58, $C54) + LEN(C58), 2) / 100, 0 )+IFERROR( MID($C54, SEARCH(C57, $C54) + LEN(C57), 2) / 100, 0 )} -> 286 | D60: {=SUM(IFERROR( VALUE(MID($C49:$G52, FIND(D58, $C49:$G52) + LEN(D58), 10)) * ISNUMBER(FIND(D58, $C49:$G52)), 0 ))+SUM(IFERROR( VALUE(MID($C49:$G52, FIND(D57, $C49:$G52) + LEN(D57), 10)) * ISNUMBER(FIND(D57, $C49:$G52)), 0 ))+IFERROR( MID($C54, SEARCH(D58, $C54) + LEN(D58), 2) / 100, 0 )+IFERROR( MID($C54, SEARCH(D57, $C54) + LEN(D57), 2) / 100, 0 )} -> 84 | O60: 20秒
...

Sheet 先锋角色库
B8: 钓鱼
B9: 装备栏 | C9: 武器 | D9: 护甲 | E9: 护手 | F9: 配件1 | G9: 配件2 | H9: 套装效果 | I9: 潜能 | R9: excel | S9: 看华法林wiki | AE9: 普攻
B10: 名称 | C10: 热熔切割器 | D10: 纾难护甲 | E10: 长息护手 | F10: 拓荒增量供氧栓一 | G10: 拓荒增量供氧栓一 | H10: =IF(COUNTIF(E10:G10,LEFT(D10,2)&"*")>=2,LEFT(D10,2), IF(COUNTIF(F10:G10,LEFT(E10,2)&"*")=2,LEFT(E10,2), "")) | I10: 5 | R10: 复制模板 | AE10: 普攻第一段倍率 | AF10: 0.23 | AG10: 0.25 | AH10: 0.27 | AI10: 0.29 | AJ10: 0.32 | AK10: 0.34 | AL10: 0.36 | AM10: 0.39 | AN10: 0.41 | AO10: 0.44 | AP10: 0.47 | AQ10: 0.51
B11: 等级 | D11: 3 | E11: 3 | F11: 3 | G11: 3 | R11: 改名字 | AE11: 普攻第二段倍率 | AF11: 0.25 | AG11: 0.28 | AH11: 0.3 | AI11: 0.33 | AJ11: 0.35 | AK11: 0.38 | AL11: 0.4 | AM11: 0.43 | AN11: 0.45 | AO11: 0.48 | AP11: 0.52 | AQ11: 0.56
B12: 词条1 | C12: =_xlfn.XLOOKUP(C10,武器库!$B:$B,武器库!$C:$C,"") -> 意志+156 | D12: =VLOOKUP(D10,护甲库!$A:$M,2+D11*3,FALSE) -> 智识149 | E12: =VLOOKUP(E10,护手库!$A:$M,2+E11*3,FALSE) -> 智识84 | F12: =VLOOKUP(F10,配件库!$A:$M,2+F11*3,FALSE) -> 智识41 | G12: =VLOOKUP(G10,配件库!$A:$M,2+G11*3,FALSE) -> 智识41 | Q12: 装备栏 | S12: 录入武器词条 | AE12: 普攻第三段倍率 | AF12: 0.35 | AG12: 0.39 | AH12: 0.42 | AI12: 0.46 | AJ12: 0.49 | AK12: 0.53 | AL12: 0.56 | AM12: 0.6 | AN12: 0.63 | AO12: 0.67 | AP12: 0.73 | AQ12: 0.79
B13: 词条2 | C13: =_xlfn.XLOOKUP(C10,武器库!$B:$B,武器库!$D:$D,"") -> 攻击力+39.0 | D13: =VLOOKUP(D10,护甲库!$A:$M,3+D11*3,FALSE) -> 0 | E13: =VLOOKUP(E10,护手库!$A:$M,3+E11*3,FALSE) -> 力量55 | F13: =VLOOKUP(F10,配件库!$A:$M,3+F11*3,FALSE) -> 敏捷27 | G13: =VLOOKUP(G10,配件库!$A:$M,3+G11*3,FALSE) -> 敏捷27 | R13: 穿好装备 | AE13: 普攻第四段倍率 | AF13: 0.37 | AG13: 0.4 | AH13: 0.44 | AI13: 0.47 | AJ13: 0.51 | AK13: 0.55 | AL13: 0.58 | AM13: 0.62 | AN13: 0.66 | AO13: 0.7 | AP13: 0.76 | AQ13: 0.82
B14: 词条3 | C14: =_xlfn.XLOOKUP(C10,武器库!$B:$B,武器库!$E:$E,"") -> 攻击力+16.0 | D14: =VLOOKUP(D10,护甲库!$A:$M,4+D11*3,FALSE) -> 充能16.7 | E14: =VLOOKUP(E10,护手库!$A:$M,4+E11*3,FALSE) -> 充能26.7 | F14: =VLOOKUP(F10,配件库!$A:$M,4+F11*3,FALSE) -> 副能力26.9 | G14: =VLOOKUP(G10,配件库!$A:$M,4+G11*3,FALSE) -> 副能力26.9 | Q14: 角色面板栏 | R14: 整理装备带给角色的面板 | AE14: 普攻第五段倍率 | AF14: 0.5 | AG14: 0.55 | AH14: 0.6 | AI14: 0.65 | AJ14: 0.7 | AK14: 0.75 | AL14: 0.8 | AM14: 0.85 | AN14: 0.9 | AO14: 0.96 | AP14: 1.04 | AQ14: 1.13
B15: 武器效果 | C15: =_xlfn.XLOOKUP(C10,武器库!$B:$B,武器库!$F:$F,"") -> 装备者通过自身技能恢复技力或获得连击状态后，全队攻击力+8.0%，持续20秒 | AE15: 处决攻击倍率 | AF15: 4 | AG15: 4.4 | AH15: 4.8 | AI15: 5.2 | AJ15: 5.6 | AK15: 6 | AL15: 6.4 | AM15: 6.8 | AN15: 7.2 | AO15: 7.7 | AP15: 8.3 | AQ15: 9
B16: 套装效果 | C16: =VLOOKUP(H10,套装效果库!A:B,2,0) -> #N/A | Q16: 技能倍率栏 | S16: 录入技能倍率 | AE16: 下落攻击倍率 | AF16: 0.8 | AG16: 0.88 | AH16: 0.96 | AI16: 1.04 | AJ16: 1.12 | AK16: 1.2 | AL16: 1.28 | AM16: 1.36 | AN16: 1.44 | AO16: 1.54 | AP16: 1.66 | AQ16: 1.8
R17: 调整自定义公式的范围
Q18: 伤害数值栏 | R18: 先录入角色面板
B19: 角色面板栏 | C19: 主能力值 | D19: 副能力值 | K19: 技能倍率 | L19: 普攻 | M19: 战技 | N19: 连携 | O19: 大招 | R19: 填写技能相关倍率 | AE19: 战技
K20: 等级 | L20: 9 | M20: 9 | N20: M1 | O20: 9 | R20: 填写角色相关buff
B21: 角色 | C21: =179+60+IF(I10>=2,20,0) -> 259 | D21: =123 -> 123 | E21: {=SUM(IFERROR( VALUE(MID($C11:$G14, SEARCH(E20, $C11:$G14) + LEN(E20), 10)) * ISNUMBER(SEARCH(E20,$C11:$G14)), 0 ))/100+IFERROR( MID($C16, SEARCH(E20, $C16) + LEN(E20), 2) / 100, 0 )} -> 0.12 | F21: {=SUM(IFERROR( VALUE(MID($C11:$G14, SEARCH(F20, $C11:$G14) + LEN(F20), 10)) * ISNUMBER(SEARCH(F20,$C11:$G14)), 0 ))/100+IFERROR( MID($C16, SEARCH(F20, $C16) + LEN(F20), 2) / 100, 0 )} -> 0.12 | G21: {=SUM(IFERROR( VALUE(MID($C11:$G14, SEARCH(G20, $C11:$G14) + LEN(G20), 10)) * ISNUMBER(SEARCH(G20,$C11:$G14)), 0 ))/100+IFERROR( MID($C16, SEARCH(G20, $C16) + LEN(G20), 2) / 100, 0 )} -> 0.12 | H21: {=SUM(IFERROR( VALUE(MID($C11:$G14, SEARCH(H20, $C11:$G14) + LEN(H20), 10)) * ISNUMBER(SEARCH(H20,$C11:$G14)), 0 ))/100+IFERROR( MID($C16, SEARCH(H20, $C16) + LEN(H20), 2) / 100, 0 )} -> 0.12 | I21: {=SUM(IFERROR( VALUE(MID($C11:$G14, SEARCH(I20, $C11:$G14) + LEN(I20), 10)) * ISNUMBER(SEARCH(I20,$C11:$G14)), 0 ))/100+IFERROR( MID($C16, SEARCH(I20, $C16) + LEN(I20), 2) / 100, 0 )} -> 0.12 | L21: {=_xlfn.XLOOKUP(L20,$AE$6:$AQ$6,AE10:AQ16,0,0,1)} -> 0 | M21: {=_xlfn.XLOOKUP(M20,$AE$6:$AQ$6,AE22:AQ29,0,0,1)} -> 0 | N21: {=_xlfn.XLOOKUP(N20,$AE$6:$AQ$6,AE34:AQ36,0,0,1)} -> 0 | O21: {=_xlfn.XLOOKUP(O20,$AE$6:$AQ$6,#REF!,0,0,1)} -> #REF! | S21: 根据天赋完善技能倍率和buff
B22: 装备 | C22: {=SUM(IFERROR( VALUE(MID($C11:$G14, FIND(C20, $C11:$G14) + LEN(C20), 10)) * ISNUMBER(FIND(C20, $C11:$G14)), 0 ))+SUM(IFERROR( VALUE(MID($C11:$G14, FIND(C19, $C11:$G14) + LEN(C19), 10)) * ISNUMBER(FIND(C19, $C11:$G14)), 0 ))+IFERROR( MID($C16, SEARCH(C20, $C16) + LEN(C20), 2) / 100, 0 )+IFERROR( MID($C16, SEARCH(C19, $C16) + LEN(C19), 2) / 100, 0 )} -> 12 | D22: {=SUM(IFERROR( VALUE(MID($C11:$G14, FIND(D20, $C11:$G14) + LEN(D20), 10)) * ISNUMBER(FIND(D20, $C11:$G14)), 0 ))+SUM(IFERROR( VALUE(MID($C11:$G14, FIND(D19, $C11:$G14) + LEN(D19), 10)) * ISNUMBER(FIND(D19, $C11:$G14)), 0 ))+IFERROR( MID($C16, SEARCH(D20, $C16) + LEN(D20), 2) / 100, 0 )+IFERROR( MID($C16, SEARCH(D19, $C16) + LEN(D19), 2) / 100, 0 )} -> 12 | S22: 根据潜能完善倍率
B23: 总计 | C23: {=ROUNDUP(SUM(C21:C22)*(1+IF(LEN(TRIM(LEFT(C19,3)))=0, 0, SUMPRODUCT( IFERROR( VALUE(MID($C11:$G14, SEARCH(LEFT(C19,3), $C11:$G14) + 3, 10)) * ISNUMBER(SEARCH(LEFT(C19,3), $C11:$G14)), 0 ) )+IFERROR( MID($C16, SEARCH(C20, $C16) + LEN(C20), 2) / 100, 0 ) )/100),0)} -> 271 | D23: {=ROUNDUP(SUM(D21:D22)*(1+IF(LEN(TRIM(LEFT(D19,3)))=0, 0, SUMPRODUCT( IFERROR( VALUE(MID($C11:$G14, SEARCH(LEFT(D19,3), $C11:$G14) + 3, 10)) * ISNUMBER(SEARCH(LEFT(D19,3), $C11:$G14)), 0 ) )+IFERROR( MID($C16, SEARCH(D20, $C16) + LEN(D20), 2) / 100, 0 ) )/100),0)} -> 208 | S23: 根据武器添加新buff
B24: 能力值加成 | C24: =C23*0.005+D23*0.002 -> 1.771
C31: 数值栏 | E31: 攻击计算器 | J31: 面板乘区 | N31: 伤害加成 | T31: 拐 | AE31: 连携
B32: 面板 | C32: 技能名称 | D32: buff名称 | E32: 基础攻击力 | F32: 百分比 | G32: 固定数值 | H32: 能力值加成 | I32: 总攻击力 | J32: 倍率 | K32: 暴击率 | L32: 暴击伤害 | M32: 源石技艺 | N32: 基础伤害加成 | O32: 普攻 | P32: 战技 | Q32: 连携 | R32: 大招 | S32: 总伤害加成 | T32: 脆弱 | U32: 增幅 | V32: 易伤 | W32: 抗性 | X32: 连击 | Y32: 失衡易伤 | Z32: 特殊加成
B33: 钓鱼面板 | H33: =C24 -> 1.771 | I33: =(E33*(1+F33)+G33)*(H33+1) -> 0
C34: 钓鱼战技 | D34: N/a | E34: =E33 -> 0 | F34: =F33 -> 0 | G34: =G33 -> 0 | H34: =H33 -> 1.771 | I34: =(E34*(1+F34)+G34)*(H34+1) -> 0 | J34: =SUM(L21:L25) -> 0 | K34: =K33 -> 0 | L34: =L33 -> 0 | M34: =M33 -> 0 | N34: =N33 -> 0 | O34: =O33 -> 0 | P34: =P33 -> 0 | Q34: =Q33 -> 0 | R34: =R33 -> 0 | T34: =T33 -> 0 | U34: =U33 -> 0 | V34: =V33 -> 0 | W34: =W33 -> 0 | X34: =X33 -> 0
C35: 钓鱼连携 | D35: N/a | E35: =E34 -> 0 | F35: =F34 -> 0 | G35: =G34 -> 0 | H35: =H34 -> 1.771 | I35: =(E35*(1+F35)+G35)*(H35+1) -> 0 | J35: =SUM(L21:L24) -> 0 | K35: =K34 -> 0 | L35: =L34 -> 0 | M35: =M34 -> 0 | N35: =N34 -> 0 | O35: =O34 -> 0 | P35: =P34 -> 0 | Q35: =Q34 -> 0 | R35: =R34 -> 0 | T35: =T34 -> 0 | U35: =U34 -> 0 | V35: =V34 -> 0 | W35: =W34 -> 0 | X35: =X34 -> 0
C36: 钓鱼大招 | D36: N/a | E36: =E35 -> 0 | F36: =F35 -> 0 | G36: =G35 -> 0 | H36: =H35 -> 1.771 | I36: =(E36*(1+F36)+G36)*(H36+1) -> 0 | J36: =L25 -> 0 | K36: =K35 -> 0 | L36: =L35 -> 0 | M36: =M35 -> 0 | N36: =N35 -> 0 | O36: =O35 -> 0 | P36: =P35 -> 0 | Q36: =Q35 -> 0 | R36: =R35 -> 0 | T36: =T35 -> 0 | U36: =U35 -> 0 | V36: =V35 -> 0 | W36: =W35 -> 0 | X36: =X35 -> 0
B37: 持续时间/s
C38: N/a | D38: 钓鱼热熔回技力 | F38: =0.08 -> 0.08
C39: N/a | D39: 钓鱼轻芒回技力 | N39: =0.048 -> 0.048
C40: N/a | D40: 钓鱼天赋钓金鱼 | F40: =IF(I10>=3,0.15,0) -> 0.15
B45: 弧光
B46: 装备栏 | C46: 武器 | D46: 护甲 | E46: 护手 | F46: 配件1 | G46: 配件2 | H46: 套装效果 | I46: 潜能 | R46: excel | S46: 看华法林wiki | AE46: 普攻
B47: 名称 | C47: 白夜新星 | D47: 清波轻甲 | E47: 轻超域护手 | F47: 清波水罐 | G47: 清波水罐 | H47: =IF(COUNTIF(E47:G47,LEFT(D47,2)&"*")>=2,LEFT(D47,2), IF(COUNTIF(F47:G47,LEFT(E47,2)&"*")=2,LEFT(E47,2), "")) -> 清波 | I47: 5 | R47: 复制模板 | AE47: 普攻第一段倍率 | AF47: 0.23 | AG47: 0.25 | AH47: 0.27 | AI47: 0.29 | AJ47: 0.32 | AK47: 0.34 | AL47: 0.36 | AM47: 0.39 | AN47: 0.41 | AO47: 0.44 | AP47: 0.47 | AQ47: 0.51
B48: 等级 | D48: 3 | E48: 3 | F48: 3 | G48: 3 | R48: 改名字 | AE48: 普攻第二段倍率 | AF48: 0.25 | AG48: 0.28 | AH48: 0.3 | AI48: 0.33 | AJ48: 0.35 | AK48: 0.38 | AL48: 0.4 | AM48: 0.43 | AN48: 0.45 | AO48: 0.48 | AP48: 0.52 | AQ48: 0.56
B49: 词条1 | C49: =_xlfn.XLOOKUP(C47,武器库!$B:$B,武器库!$C:$C,"") -> 主能力值+132 | D49: =VLOOKUP(D47,护甲库!$A:$M,2+D48*3,FALSE) -> 智识113 | E49: =VLOOKUP(E47,护手库!$A:$M,2+E48*3,FALSE) -> 敏捷84 | F49: =VLOOKUP(F47,配件库!$A:$M,2+F48*3,FALSE) -> 智识41 | G49: =VLOOKUP(G47,配件库!$A:$M,2+G48*3,FALSE) -> 智识41 | Q49: 装备栏 | S49: 录入武器词条 | AE49: 普攻第三段倍率 | AF49: 0.35 | AG49: 0.39 | AH49: 0.42 | AI49: 0.46 | AJ49: 0.49 | AK49: 0.53 | AL49: 0.56 | AM49: 0.6 | AN49: 0.63 | AO49: 0.67 | AP49: 0.73 | AQ49: 0.79
B50: 词条2 | C50: =_xlfn.XLOOKUP(C47,武器库!$B:$B,武器库!$D:$D,"") -> 源石技艺+78 | D50: =VLOOKUP(D47,护甲库!$A:$M,3+D48*3,FALSE) -> 意志75 | E50: =VLOOKUP(E47,护手库!$A:$M,3+E48*3,FALSE) -> 力量55 | F50: =VLOOKUP(F47,配件库!$A:$M,3+F48*3,FALSE) -> 意志27 | G50: =VLOOKUP(G47,配件库!$A:$M,3+G48*3,FALSE) -> 意志27 | R50: 穿好装备 | AE50: 普攻第四段倍率 | AF50: 0.37 | AG50: 0.4 | AH50: 0.44 | AI50: 0.47 | AJ50: 0.51 | AK50: 0.55 | AL50: 0.58 | AM50: 0.62 | AN50: 0.66 | AO50: 0.7 | AP50: 0.76 | AQ50: 0.82
B51: 词条3 | C51: =_xlfn.XLOOKUP(C47,武器库!$B:$B,武器库!$E:$E,"") -> 法术伤害+19.2 | D51: =VLOOKUP(D47,护甲库!$A:$M,4+D48*3,FALSE) -> 技艺26 | E51: =VLOOKUP(E47,护手库!$A:$M,4+E48*3,FALSE) -> 技艺44 | F51: =VLOOKUP(F47,配件库!$A:$M,4+F48*3,FALSE) -> 技艺53 | G51: =VLOOKUP(G47,配件库!$A:$M,4+G48*3,FALSE) -> 技艺53 | Q51: 角色面板栏 | R51: 整理装备带给角色的面板 | AE51: 普攻第五段倍率 | AF51: 0.5 | AG51: 0.55 | AH51: 0.6 | AI51: 0.65 | AJ51: 0.7 | AK51: 0.75 | AL51: 0.8 | AM51: 0.85 | AN51: 0.9 | AO51: 0.96 | AP51: 1.04 | AQ51: 1.13
B52: 武器效果 | C52: =_xlfn.XLOOKUP(C47,武器库!$B:$B,武器库!$F:$F,"") -> 装备者施加燃烧或导电后，法术+伤害+19.2，源石技艺强度+40，持续15秒。 | AE52: 处决攻击倍率 | AF52: 4 | AG52: 4.4 | AH52: 4.8 | AI52: 5.2 | AJ52: 5.6 | AK52: 6 | AL52: 6.4 | AM52: 6.8 | AN52: 7.2 | AO52: 7.7 | AP52: 8.3 | AQ52: 9
B53: 套装效果 | C53: =VLOOKUP(H47,套装效果库!A:B,2,0) -> 连携技冷却缩减+15。当装备者施放连携技时，所有技能伤害+20.0%，持续15秒。该效果最多叠加2层，每层单独计算持续时间。 | Q53: 技能倍率栏 | S53: 录入技能倍率 | AE53: 下落攻击倍率 | AF53: 0.8 | AG53: 0.88 | AH53: 0.96 | AI53: 1.04 | AJ53: 1.12 | AK53: 1.2 | AL53: 1.28 | AM53: 1.36 | AN53: 1.44 | AO53: 1.54 | AP53: 1.66 | AQ53: 1.8
R54: 调整自定义公式的范围
Q55: 伤害数值栏 | R55: 先录入角色面板
B56: 角色面板栏 | C56: 主能力值 | D56: 副能力值 | K56: 技能倍率 | L56: 普攻 | M56: 战技 | N56: 连携 | O56: 大招 | R56: 填写技能相关倍率 | AE56: 战技
D57: 智识 | E57: 技艺 | K57: 等级 | L57: 9 | M57: 9 | N57: 9 | O57: 9 | R57: 填写角色相关buff
...

Sheet 主c角色库
B1: 观前提示 | C1: 制作一个主c的技能伤害倍率和buff数值表，他需要对zmd的伤害计算有一定的理解 | L1: 面板属性和buff | M1: 面板属性是入场是指没有任何buff图标加成的
C2: 为了制作这个表，我想要不管你的角色什么练度，潜能，技能等级，都能计算出伤害，而不是只能算满潜满级的这种一次性伤害计算器 | L2: buff | M2: 有触发条件，触发后在一段时间内生效，有buff图标
C3: 正因为为了这个灵活性，所以对excel也有一定的门槛，而如果解释这些的话视频就会很长。
C4: 制作这个视频真的花费了我大量的精力，也希望你们能快速的使用这个计算器为了自己喜欢的角色排轴算伤害，为终末地的社区建设出一份力
B6: 详细队伍数据 | AF6: 1 | AG6: 2 | AH6: 3 | AI6: 4 | AJ6: 5 | AK6: 6 | AL6: 7 | AM6: 8 | AN6: 9 | AO6: M1 | AP6: M2 | AQ6: M3
B7: 洛茜
C8: 武器 | D8: 护甲 | E8: 护手 | F8: 配件1 | G8: 配件2 | H8: 套装效果 | I8: 潜能 | AE8: 普攻
B9: 名称 | C9: 狼之绯 | D9: 警用护甲一 | E9: 警用手套一 | F9: 警用瞄具一 | G9: 生物辅助护板 | H9: =IF(COUNTIF(E9:G9,LEFT(D9,2)&"*")>=2,LEFT(D9,2), IF(COUNTIF(F9:G9,LEFT(E9,2)&"*")=2,LEFT(E9,2), "")) -> 警用 | I9: 0 | AF9: 1 | AG9: 2 | AH9: 3 | AI9: 4 | AJ9: 5 | AK9: 6 | AL9: 7 | AM9: 8 | AN9: 9 | AO9: M1 | AP9: M2 | AQ9: M3
B10: 等级 | D10: 3 | E10: 3 | F10: 3 | G10: 3 | AE10: 普攻第一段倍率 | AF10: 0.27 | AG10: 0.3 | AH10: 0.32 | AI10: 0.35 | AJ10: 0.38 | AK10: 0.41 | AL10: 0.43 | AM10: 0.46 | AN10: 0.49 | AO10: 0.52 | AP10: 0.56 | AQ10: 0.61
B11: 词条1 | C11: =_xlfn.XLOOKUP(C9,武器库!$B:$B,武器库!$C:$C,"") -> 敏捷+156 | D11: =VLOOKUP(D9,护甲库!$A:$M,2+D10*3,FALSE) -> 敏捷113 | E11: =VLOOKUP(E9,护手库!$A:$M,2+E10*3,FALSE) -> 敏捷84 | F11: =VLOOKUP(F9,配件库!$A:$M,2+F10*3,FALSE) -> 敏捷41 | G11: =VLOOKUP(G9,配件库!$A:$M,2+G10*3,FALSE) -> 意志41 | AE11: 普攻第二段倍率 | AF11: 0.32 | AG11: 0.35 | AH11: 0.38 | AI11: 0.41 | AJ11: 0.44 | AK11: 0.47 | AL11: 0.5 | AM11: 0.54 | AN11: 0.57 | AO11: 0.61 | AP11: 0.65 | AQ11: 0.71
B12: 词条2 | C12: =_xlfn.XLOOKUP(C9,武器库!$B:$B,武器库!$D:$D,"") -> 暴击19.5 | D12: =VLOOKUP(D9,护甲库!$A:$M,3+D10*3,FALSE) -> 智识75 | E12: =VLOOKUP(E9,护手库!$A:$M,3+E10*3,FALSE) -> 智识55 | F12: =VLOOKUP(F9,配件库!$A:$M,3+F10*3,FALSE) -> 智识27 | G12: =VLOOKUP(G9,配件库!$A:$M,3+G10*3,FALSE) -> 智识27 | AE12: 普攻第三段倍率 | AF12: 0.34 | AG12: 0.37 | AH12: 0.41 | AI12: 0.44 | AJ12: 0.48 | AK12: 0.51 | AL12: 0.54 | AM12: 0.58 | AN12: 0.61 | AO12: 0.65 | AP12: 0.71 | AQ12: 0.77
B13: 词条3 | C13: =_xlfn.XLOOKUP(C9,武器库!$B:$B,武器库!$E:$E,"") -> 攻击力25.6 | D13: =VLOOKUP(D9,护甲库!$A:$M,4+D10*3,FALSE) -> 充能16.0 | E13: =VLOOKUP(E9,护手库!$A:$M,4+E10*3,FALSE) -> 终结技56.1 | F13: =VLOOKUP(F9,配件库!$A:$M,4+F10*3,FALSE) -> 暴击13.5 | G13: =VLOOKUP(G9,配件库!$A:$M,4+G10*3,FALSE) -> 主能力26.9 | AE13: 普攻第四段倍率 | AF13: 0.41 | AG13: 0.45 | AH13: 0.49 | AI13: 0.53 | AJ13: 0.57 | AK13: 0.61 | AL13: 0.65 | AM13: 0.69 | AN13: 0.73 | AO13: 0.78 | AP13: 0.84 | AQ13: 0.91
B14: 武器效果 | C14: =_xlfn.XLOOKUP(C9,武器库!$B:$B,武器库!$F:$F,"") -> 装备者造成暴击伤害后，获得1层狼血，物理和灼热伤害+1.6%，最多叠加16层。当狼血叠加至16层后，物理和灼热伤害额外+38.4%，持续20秒。持续时间结束后，清空所有狼血叠加层数。 | AE14: 普攻第五段倍率 | AF14: 0.5 | AG14: 0.55 | AH14: 0.6 | AI14: 0.65 | AJ14: 0.7 | AK14: 0.75 | AL14: 0.8 | AM14: 0.85 | AN14: 0.9 | AO14: 0.96 | AP14: 1.04 | AQ14: 1.13
B15: 套装效果 | C15: =VLOOKUP(H9,套装效果库!A:B,2,0) -> 暴击05。当触发暴击后，5秒内+5%攻击力，该效果最多叠加5层。层数叠满后，额外+5%暴击率，该效果无法叠加。 | AE15: 处决攻击倍率 | AF15: 4 | AG15: 4.4 | AH15: 4.8 | AI15: 5.2 | AJ15: 5.6 | AK15: 6 | AL15: 6.4 | AM15: 6.8 | AN15: 7.2 | AO15: 7.7 | AP15: 8.3 | AQ15: 9
AE16: 下落攻击倍率 | AF16: 0.8 | AG16: 0.88 | AH16: 0.96 | AI16: 1.04 | AJ16: 1.12 | AK16: 1.2 | AL16: 1.28 | AM16: 1.36 | AN16: 1.44 | AO16: 1.54 | AP16: 1.66 | AQ16: 1.8
C18: 主能力值 | D18: 副能力值 | L18: 普攻 | M18: 战技 | N18: 连携 | O18: 大招 | AE18: 战技
C19: 敏捷 | D19: 智识 | E19: 攻击力 | F19: 充能 | G19: 终结技 | H19: 暴击 | K19: 等级 | L19: M3 | M19: M3 | N19: M3 | O19: M3 | AF19: 1 | AG19: 2 | AH19: 3 | AI19: 4 | AJ19: 5 | AK19: 6 | AL19: 7 | AM19: 8 | AN19: 9 | AO19: M1 | AP19: M2 | AQ19: M3
B20: 角色 | C20: =176+60+IF(I9>=2,20,0) -> 236 | D20: 118 | E20: {=SUM(IFERROR( VALUE(MID($C10:$G13, SEARCH(E19, $C10:$G13) + LEN(E19), 10)) * ISNUMBER(SEARCH(E19,$C10:$G13)), 0 ))/100+IFERROR( MID($C15, SEARCH(E19, $C15) + LEN(E19), 2) / 100, 0 )} -> 0.256 | F20: {=SUM(IFERROR( VALUE(MID($C10:$G13, SEARCH(F19, $C10:$G13) + LEN(F19), 10)) * ISNUMBER(SEARCH(F19,$C10:$G13)), 0 ))/100+IFERROR( MID($C15, SEARCH(F19, $C15) + LEN(F19), 2) / 100, 0 )} -> 0.16 | G20: {=SUM(IFERROR( VALUE(MID($C10:$G13, SEARCH(G19, $C10:$G13) + LEN(G19), 10)) * ISNUMBER(SEARCH(G19,$C10:$G13)), 0 ))/100+IFERROR( MID($C15, SEARCH(G19, $C15) + LEN(G19), 2) / 100, 0 )} -> 0.561 | H20: {=SUM(IFERROR( VALUE(MID($C10:$G13, SEARCH(H19, $C10:$G13) + LEN(H19), 10)) * ISNUMBER(SEARCH(H19,$C10:$G13)), 0 ))/100+IFERROR( MID($C15, SEARCH(H19, $C15) + LEN(H19), 2) / 100, 0 )} -> 0.38 | I20: {=SUM(IFERROR( VALUE(MID($C10:$G13, SEARCH(I19, $C10:$G13) + LEN(I19), 10)) * ISNUMBER(SEARCH(I19,$C10:$G13)), 0 ))/100+IFERROR( MID($C15, SEARCH(I19, $C15) + LEN(I19), 2) / 100, 0 )} -> 0.12 | K20: 技能倍率 | L20: {=_xlfn.XLOOKUP(L19,$AE$6:$AQ$6,AE10:AQ16,0,0,1)} -> 0.61 | M20: {=_xlfn.XLOOKUP(M19,$AE$6:$AQ$6,AE20:AQ23,0,0,1)} -> 1.92 | N20: {=_xlfn.XLOOKUP(N19,$AE$6:$AQ$6,AE27:AQ34,0,0,1)} -> 14s | O20: {=_xlfn.XLOOKUP(O19,$AE$6:$AQ$6,AE38:AQ43,0,0,1)} -> 110 | AE20: 第一段伤害倍率 | AF20: 0.85 | AG20: 0.94 | AH20: 1.02 | AI20: 1.11 | AJ20: 1.19 | AK20: 1.28 | AL20: 1.37 | AM20: 1.45 | AN20: 1.54 | AO20: 1.64 | AP20: 1.77 | AQ20: 1.92
B21: 装备 | C21: {=SUM(IFERROR( VALUE(MID($C10:$G13, FIND(C19, $C10:$G13) + LEN(C19), 10)) * ISNUMBER(FIND(C19, $C10:$G13)), 0 ))+SUM(IFERROR( VALUE(MID($C10:$G13, FIND(C18, $C10:$G13) + LEN(C18), 10)) * ISNUMBER(FIND(C18, $C10:$G13)), 0 ))+IFERROR( MID($C15, SEARCH(C19, $C15) + LEN(C19), 2) / 100, 0 )+IFERROR( MID($C15, SEARCH(C18, $C15) + LEN(C18), 2) / 100, 0 )} -> 394 | D21: {=SUM(IFERROR( VALUE(MID($C10:$G13, FIND(D19, $C10:$G13) + LEN(D19), 10)) * ISNUMBER(FIND(D19, $C10:$G13)), 0 ))+SUM(IFERROR( VALUE(MID($C10:$G13, FIND(D18, $C10:$G13) + LEN(D18), 10)) * ISNUMBER(FIND(D18, $C10:$G13)), 0 ))+IFERROR( MID($C15, SEARCH(D19, $C15) + LEN(D19), 2) / 100, 0 )+IFERROR( MID($C15, SEARCH(D18, $C15) + LEN(D18), 2) / 100, 0 )} -> 184 | L21: 0.71 | M21: 5 | N21: 1.5 | O21: 6 | AE21: 第一段失衡值 | AF21: 5 | AG21: 5 | AH21: 5 | AI21: 5 | AJ21: 5 | AK21: 5 | AL21: 5 | AM21: 5 | AN21: 5 | AO21: 5 | AP21: 5 | AQ21: 5
B22: 总计 | C22: {=ROUNDUP(SUM(C20:C21)*(1+IF(LEN(TRIM(LEFT(C18,3)))=0, 0, SUMPRODUCT( IFERROR( VALUE(MID($C10:$G13, SEARCH(LEFT(C18,3), $C10:$G13) + 3, 10)) * ISNUMBER(SEARCH(LEFT(C18,3), $C10:$G13)), 0 ) )+IFERROR( MID($C15, SEARCH(C19, $C15) + LEN(C19), 2) / 100, 0 ) )/100),0)} -> 800 | D22: {=ROUNDUP(SUM(D20:D21)*(1+IF(LEN(TRIM(LEFT(D18,3)))=0, 0, SUMPRODUCT( IFERROR( VALUE(MID($C10:$G13, SEARCH(LEFT(D18,3), $C10:$G13) + 3, 10)) * ISNUMBER(SEARCH(LEFT(D18,3), $C10:$G13)), 0 ) )+IFERROR( MID($C15, SEARCH(D19, $C15) + LEN(D19), 2) / 100, 0 ) )/100),0)} -> 302 | L22: 0.77 | M22: 2.88 | N22: 3 | O22: 2.5 | AE22: 第二段伤害倍率 | AF22: 1.28 | AG22: 1.41 | AH22: 1.53 | AI22: 1.66 | AJ22: 1.79 | AK22: 1.92 | AL22: 2.04 | AM22: 2.17 | AN22: 2.3 | AO22: 2.46 | AP22: 2.65 | AQ22: 2.88
B23: 能力值加成 | C23: =C22*0.005+D22*0.002 -> 4.604 | L23: 0.91 | M23: 15 | N23: 1.8 | O23: 7.5 | AE23: 第二段失衡值 | AF23: 10 | AG23: 10 | AH23: 10 | AI23: 10 | AJ23: 10 | AK23: 10 | AL23: 10 | AM23: 10 | AN23: 12 | AO23: 12 | AP23: 12 | AQ23: 15
L24: 1.13 | N24: 5 | O24: 25
L25: 9 | N25: 0.25 | O25: 0.6 | AE25: 连携
L26: 1.8 | N26: 0.5 | AF26: 1 | AG26: 2 | AH26: 3 | AI26: 4 | AJ26: 5 | AK26: 6 | AL26: 7 | AM26: 8 | AN26: 9 | AO26: M1 | AP26: M2 | AQ26: M3
N27: 15 | AE27: 冷却时间 | AF27: 15s | AG27: 15s | AH27: 15s | AI27: 15s | AJ27: 15s | AK27: 15s | AL27: 15s | AM27: 15s | AN27: 15s | AO27: 15s | AP27: 15s | AQ27: 14s
AE28: 第一段伤害倍率 | AF28: 0.67 | AG28: 0.73 | AH28: 0.8 | AI28: 0.87 | AJ28: 0.93 | AK28: 1 | AL28: 1.07 | AM28: 1.13 | AN28: 1.2 | AO28: 1.28 | AP28: 1.38 | AQ28: 1.5
AE29: 第二段伤害倍率 | AF29: 1.33 | AG29: 1.47 | AH29: 1.6 | AI29: 1.73 | AJ29: 1.87 | AK29: 2 | AL29: 2.13 | AM29: 2.27 | AN29: 2.4 | AO29: 2.57 | AP29: 2.77 | AQ29: 3
C30: 数值栏 | E30: 攻击计算器 | J30: 面板乘区 | N30: 伤害加成 | T30: 拐 | AE30: 消耗每层附着额外伤害倍率 | AF30: 0.8 | AG30: 0.88 | AH30: 0.96 | AI30: 1.04 | AJ30: 1.12 | AK30: 1.2 | AL30: 1.28 | AM30: 1.36 | AN30: 1.44 | AO30: 1.54 | AP30: 1.66 | AQ30: 1.8
B31: 面板 | C31: 技能名称 | D31: buff名称 | E31: 基础攻击力 | F31: 百分比 | G31: 固定数值 | H31: 能力值加成 | I31: 总攻击力 | J31: 倍率 | K31: 暴击率 | L31: 暴击伤害 | M31: 源石技艺 | N31: 基础伤害加成 | O31: 普攻 | P31: 战技 | Q31: 连携 | R31: 大招 | S31: 总伤害加成 | T31: 脆弱 | U31: 增幅 | V31: 易伤 | W31: 抗性 | X31: 连击 | Y31: 失衡易伤 | Z31: 特殊加成 | AE31: 第二段失衡值 | AF31: 5 | AG31: 5 | AH31: 5 | AI31: 5 | AJ31: 5 | AK31: 5 | AL31: 5 | AM31: 5 | AN31: 5 | AO31: 5 | AP31: 5 | AQ31: 5
B32: 洛茜面板 | E32: =828 -> 828 | F32: =$E$20 -> 0.256 | H32: =$C$23 -> 4.604 | I32: =(E32*(1+F32)+G32)*(H32+1) -> 5827.9807 | K32: =$H$20 -> 0.38 | L32: =0.5 -> 0.5 | R32: =$G$20 -> 0.561 | AE32: 暴击率提升 | AF32: 0.15 | AG32: 0.15 | AH32: 0.15 | AI32: 0.17 | AJ32: 0.17 | AK32: 0.17 | AL32: 0.19 | AM32: 0.19 | AN32: 0.21 | AO32: 0.21 | AP32: 0.23 | AQ32: 0.25
C33: 洛茜普攻 | D33: N/a | E33: =828 -> 828 | F33: =$E$20 -> 0.256 | H33: =$C$23 -> 4.604 | I33: =(E33*(1+F33)+G33)*(H33+1) -> 5827.9807 | J33: =SUM(L20:L24) -> 4.13 | K33: =K32 -> 0.38 | L33: =0.5 -> 0.5 | R33: =$G$20 -> 0.561 | AE33: 暴击伤害提升 | AF33: 0.3 | AG33: 0.3 | AH33: 0.3 | AI33: 0.34 | AJ33: 0.34 | AK33: 0.34 | AL33: 0.38 | AM33: 0.38 | AN33: 0.42 | AO33: 0.42 | AP33: 0.46 | AQ33: 0.5
C34: 洛茜前段普攻 | D34: N/a | E34: =828 -> 828 | F34: =$E$20 -> 0.256 | H34: =$C$23 -> 4.604 | I34: =(E34*(1+F34)+G34)*(H34+1) -> 5827.9807 | J34: =SUM($L$20:$L$23) -> 3 | K34: =K33 -> 0.38 | L34: =0.5 -> 0.5 | R34: =$G$20 -> 0.561 | AE34: 增益效果的持续时间（秒） | AF34: 15 | AG34: 15 | AH34: 15 | AI34: 15 | AJ34: 15 | AK34: 15 | AL34: 15 | AM34: 15 | AN34: 15 | AO34: 15 | AP34: 15 | AQ34: 15
C35: 洛茜重击普攻 | D35: N/a | E35: =828 -> 828 | F35: =$E$20 -> 0.256 | H35: =$C$23 -> 4.604 | I35: =(E35*(1+F35)+G35)*(H35+1) -> 5827.9807 | J35: =$L$24 -> 1.13 | K35: =K34 -> 0.38 | L35: =0.5 -> 0.5 | R35: =$G$20 -> 0.561
C36: 洛茜处决普攻 | D36: N/a | E36: =828 -> 828 | F36: =$E$20 -> 0.256 | H36: =$C$23 -> 4.604 | I36: =(E36*(1+F36)+G36)*(H36+1) -> 5827.9807 | J36: =$L$25 -> 9 | K36: =K35 -> 0.38 | L36: =0.5 -> 0.5 | R36: =$G$20 -> 0.561 | AE36: 大招
C37: 洛茜下落普攻 | D37: N/a | E37: =828 -> 828 | F37: =$E$20 -> 0.256 | H37: =$C$23 -> 4.604 | I37: =(E37*(1+F37)+G37)*(H37+1) -> 5827.9807 | J37: =L26 -> 1.8 | K37: =K36 -> 0.38 | L37: =0.5 -> 0.5 | R37: =$G$20 -> 0.561 | AF37: 1 | AG37: 2 | AH37: 3 | AI37: 4 | AJ37: 5 | AK37: 6 | AL37: 7 | AM37: 8 | AN37: 9 | AO37: M1 | AP37: M2 | AQ37: M3
C38: 洛茜战技 | D38: N/a | E38: =828 -> 828 | F38: =$E$20 -> 0.256 | H38: =$C$23 -> 4.604 | I38: =(E38*(1+F38)+G38)*(H38+1) -> 5827.9807 | J38: =($M$20+$M$22)*(IF($I$9>=1,1.15,1)) -> 4.8 | K38: =K37 -> 0.38 | L38: =0.5 -> 0.5 | R38: =$G$20 -> 0.561 | AE38: 所需终结技能量 | AF38: 110 | AG38: 110 | AH38: 110 | AI38: 110 | AJ38: 110 | AK38: 110 | AL38: 110 | AM38: 110 | AN38: 110 | AO38: 110 | AP38: 110 | AQ38: 110
C39: 洛茜前段战技 | D39: N/a | E39: =828 -> 828 | F39: =$E$20 -> 0.256 | H39: =$C$23 -> 4.604 | I39: =(E39*(1+F39)+G39)*(H39+1) -> 5827.9807 | J39: =(M20)*(IF($I$9>=1,1.15,1)) -> 1.92 | K39: =K38 -> 0.38 | L39: =0.5 -> 0.5 | R39: =$G$20 -> 0.561 | AE39: 戳击总伤害倍率 | AF39: 2.75 | AG39: 3 | AH39: 3.25 | AI39: 3.5 | AJ39: 3.75 | AK39: 4 | AL39: 4.25 | AM39: 4.5 | AN39: 4.75 | AO39: 5.25 | AP39: 5.5 | AQ39: 6
C40: 洛茜狼之珀战技 | D40: N/a | E40: =828 -> 828 | F40: =$E$20 -> 0.256 | H40: =$C$23 -> 4.604 | I40: =(E40*(1+F40)+G40)*(H40+1) -> 5827.9807 | J40: =(M22)*(IF($I$9>=1,1.15,1)) -> 2.88 | K40: =K39 -> 0.38 | L40: =0.5 -> 0.5 | R40: =$G$20 -> 0.561 | AE40: 第一段斩击伤害倍率 | AF40: 1.11 | AG40: 1.22 | AH40: 1.33 | AI40: 1.44 | AJ40: 1.56 | AK40: 1.67 | AL40: 1.78 | AM40: 1.89 | AN40: 2 | AO40: 2.14 | AP40: 2.31 | AQ40: 2.5
C41: 洛茜零层连携 | D41: N/a | E41: =828 -> 828 | F41: =$E$20 -> 0.256 | H41: =$C$23 -> 4.604 | I41: =(E41*(1+F41)+G41)*(H41+1) -> 5827.9807 | J41: =($N$21+$N$22)*(IF($I$9>=1,1.15,1)) -> 4.5 | K41: =K47 -> 0.38 | L41: =0.5 -> 0.5 | R41: =$G$20 -> 0.561 | AE41: 第二段斩击伤害倍率 | AF41: 3.33 | AG41: 3.67 | AH41: 4 | AI41: 4.33 | AJ41: 4.67 | AK41: 5 | AL41: 5.34 | AM41: 5.67 | AN41: 6 | AO41: 6.42 | AP41: 6.92 | AQ41: 7.5
C42: 洛茜一层连携 | D42: N/a | E42: =828 -> 828 | F42: =$E$20 -> 0.256 | H42: =$C$23 -> 4.604 | I42: =(E42*(1+F42)+G42)*(H42+1) -> 5827.9807 | J42: =($N$21+$N$22+$N$23)*(IF($I$9>=1,1.15,1)) -> 6.3 | K42: =K41 -> 0.38 | L42: =0.5 -> 0.5 | R42: =$G$20 -> 0.561 | AE42: 失衡值 | AF42: 25 | AG42: 25 | AH42: 25 | AI42: 25 | AJ42: 25 | AK42: 25 | AL42: 25 | AM42: 25 | AN42: 25 | AO42: 25 | AP42: 25 | AQ42: 25
...

Sheet 护甲库
A1: 精锻等级 | B1: 0 | E1: 1 | H1: 2 | K1: 3
A2: 名称 | B2: 词条1 | C2: 词条2 | D2: 词条3 | E2: 词条1 | F2: 词条2 | G2: 词条3 | H2: 词条1 | I2: 词条2 | J2: 词条3 | K2: 词条1 | L2: 词条2 | M2: 词条3
A3: 拓荒护甲 | B3: 力量87 | C3: 智识58 | D3: 终结技25.9 | E3: 力量95 | F3: 智识63 | G3: 终结技28.5 | H3: 力量104 | I3: 智识69 | J3: 终结技31.1 | K3: 力量113 | L3: 智识75 | M3: 终结技33.6
A4: 拓荒护甲一 | B4: 力量87 | C4: 敏捷58 | D4: 战技20.7 | E4: 力量95 | F4: 敏捷63 | G4: 战技22.8 | H4: 力量104 | I4: 敏捷69 | J4: 战技24.8 | K4: 力量113 | L4: 敏捷75 | M4: 战技26.9
A5: 拓荒护甲二 | B5: 敏捷87 | C5: 智识58 | D5: 战技20.7 | E5: 敏捷95 | F5: 智识63 | G5: 战技22.8 | H5: 敏捷104 | I5: 智识69 | J5: 战技24.8 | K5: 敏捷113 | L5: 智识75 | M5: 战技26.9
A6: 拓荒护甲三 | B6: 敏捷87 | C6: 智识58 | D6: 副能力10.4 | E6: 敏捷95 | F6: 智识63 | G6: 副能力11.4 | H6: 敏捷104 | I6: 智识69 | J6: 副能力12.4 | K6: 敏捷113 | L6: 智识75 | M6: 副能力13.5
A7: 拓荒护服 | B7: 智识87 | C7: 敏捷58 | D7: 充能12.3 | E7: 智识95 | F7: 敏捷63 | G7: 充能13.6 | H7: 智识104 | I7: 敏捷69 | J7: 充能14.8 | K7: 智识113 | L7: 敏捷75 | M7: 充能16.0
A8: 应龙重甲 | B8: 力量87 | C8: 意志58 | D8: 物伤11.5 | E8: 力量95 | F8: 意志63 | G8: 物伤12.7 | H8: 力量104 | I8: 意志69 | J8: 物伤13.8 | K8: 力量113 | L8: 意志75 | M8: 物伤14.9
A9: 应龙重甲一 | B9: 敏捷87 | C9: 力量58 | D9: 充能12.3 | E9: 敏捷95 | F9: 力量63 | G9: 充能13.6 | H9: 敏捷104 | I9: 力量69 | J9: 充能14.8 | K9: 敏捷113 | L9: 力量75 | M9: 充能16.0
A10: 应龙重甲二 | B10: 敏捷87 | C10: 智识58 | D10: 连携伤20.7 | E10: 敏捷95 | F10: 智识63 | G10: 连携伤22.8 | H10: 敏捷104 | I10: 智识69 | J10: 连携伤24.8 | K10: 敏捷113 | L10: 智识75 | M10: 连携伤26.9
A11: 应龙轻甲 | B11: 意志87 | C11: 力量58 | D11: 全技伤13.8 | E11: 意志95 | F11: 力量63 | G11: 全技伤15.2 | H11: 意志104 | I11: 力量69 | J11: 全技伤16.6 | K11: 意志113 | L11: 力量75 | M11: 全技伤17.9
A12: 碾骨披巾 | B12: 意志87 | C12: 力量58 | D12: 连携伤20.7 | E12: 意志95 | F12: 力量63 | G12: 连携伤22.8 | H12: 意志104 | I12: 力量69 | J12: 连携伤24.8 | K12: 意志113 | L12: 力量75 | M12: 连携伤26.9
A13: 碾骨披巾一 | B13: 意志87 | C13: 敏捷58 | D13: 充能12.3 | E13: 意志95 | F13: 敏捷63 | G13: 充能13.6 | H13: 意志104 | I13: 敏捷69 | J13: 充能14.8 | K13: 意志113 | L13: 敏捷75 | M13: 充能16.0
... A35: 长息装甲 | B35: 意志87 | C35: 智识58 | D35: 技艺20 | E35: 意志95 | F35: 智识63 | G35: 技艺22 | H35: 意志104 | I35: 智识69 | J35: 技艺24 | K35: 意志113 | L35: 智识75 | M35: 技艺26
A36: 纾难护甲 | B36: 智识115 | D36: 充能12.9 | E36: 智识126 | G36: 充能14.1 | H36: 智识138 | J36: 充能15.4 | K36: 智识149 | M36: 充能16.7
A37: 纾难重甲 | B37: 敏捷115 | D37: 普攻14.4 | E37: 敏捷126 | G37: 普攻15.8 | H37: 敏捷138 | J37: 普攻17.3 | K37: 敏捷149 | M37: 普攻18.7

Sheet 护手库
A1: 精锻等级 | B1: 0 | E1: 1 | H1: 2 | K1: 3
A2: 名称 | B2: 词条1 | C2: 词条2 | D2: 词条3 | E2: 词条1 | F2: 词条2 | G2: 词条3 | H2: 词条1 | I2: 词条2 | J2: 词条3 | K2: 词条1 | L2: 词条2 | M2: 词条3
A3: 拓荒耐蚀手套 | B3: 敏捷65 | C3: 智识43 | D3: 战技34.5 | E3: 敏捷71 | F3: 智识47 | G3: 战技38.0 | H3: 敏捷78 | I3: 智识51 | J3: 战技41.4 | K3: 敏捷84 | L3: 智识55 | M3: 战技44.9
A4: 拓荒纤维手套 | B4: 意志65 | C4: 力量43 | D4: 全技伤23.0 | E4: 意志71 | F4: 力量47 | G4: 全技伤25.3 | H4: 意志78 | I4: 力量51 | J4: 全技伤27.6 | K4: 意志84 | L4: 力量55 | M4: 全技伤29.9
A5: 拓荒纤维手套一 | B5: 智识65 | C5: 敏捷43 | D5: 充能20.5 | E5: 智识71 | F5: 敏捷47 | G5: 充能22.6 | H5: 智识78 | I5: 敏捷51 | J5: 充能24.6 | K5: 智识84 | L5: 敏捷55 | M5: 充能26.7
A6: 应龙护手一 | B6: 意志65 | C6: 敏捷43 | D6: 连携伤34.5 | E6: 意志71 | F6: 敏捷47 | G6: 连携伤38.0 | H6: 意志78 | I6: 敏捷51 | J6: 连携伤41.4 | K6: 意志84 | L6: 敏捷55 | M6: 连携伤44.9
A7: 应龙护手 | B7: 敏捷65 | C7: 智识43 | D7: 连携伤34.5 | E7: 敏捷71 | F7: 智识47 | G7: 连携伤38.0 | H7: 敏捷78 | I7: 智识51 | J7: 连携伤41.4 | K7: 敏捷84 | L7: 智识55 | M7: 连携伤44.9
A8: 碾骨腕带一 | B8: 敏捷65 | C8: 力量43 | D8: 冰电伤19.2 | E8: 敏捷71 | F8: 力量47 | G8: 冰电伤21.1 | H8: 敏捷78 | I8: 力量51 | J8: 冰电伤23.0 | K8: 敏捷84 | L8: 力量55 | M8: 冰电伤24.9
A9: 碾骨腕带 | B9: 力量65 | C9: 敏捷43 | D9: 灼自伤19.2 | E9: 力量71 | F9: 敏捷47 | G9: 灼自伤21.1 | H9: 力量78 | I9: 敏捷51 | J9: 灼自伤23.0 | K9: 力量84 | L9: 敏捷55 | M9: 灼自伤24.9
A10: 碾骨手套 | B10: 意志65 | C10: 敏捷43 | D10: 冰电伤19.2 | E10: 意志71 | F10: 敏捷47 | G10: 冰电伤21.1 | H10: 意志78 | I10: 敏捷51 | J10: 冰电伤23.0 | K10: 意志84 | L10: 敏捷55 | M10: 冰电伤24.9
A11: 潮涌手甲 | B11: 力量65 | C11: 意志43 | D11: 冰电伤19.2 | E11: 力量71 | F11: 意志47 | G11: 冰电伤21.1 | H11: 力量78 | I11: 意志51 | J11: 冰电伤23.0 | K11: 力量84 | L11: 意志55 | M11: 冰电伤24.9
A12: 清波手甲 | B12: 敏捷65 | C12: 力量43 | D12: 全技伤23.0 | E12: 敏捷71 | F12: 力量47 | G12: 全技伤25.3 | H12: 敏捷78 | I12: 力量51 | J12: 全技伤27.6 | K12: 敏捷84 | L12: 力量55 | M12: 全技伤29.9
A13: 清波护手 | B13: 智识65 | C13: 意志43 | D13: 充能20.5 | E13: 智识71 | F13: 意志47 | G13: 充能22.6 | H13: 智识78 | I13: 意志51 | J13: 充能24.6 | K13: 智识84 | L13: 意志55 | M13: 充能26.7
... A31: 长息护手 | B31: 智识65 | C31: 力量43 | D31: 充能20.5 | E31: 智识71 | F31: 力量47 | G31: 充能22.6 | H31: 智识78 | I31: 力量51 | J31: 充能24.6 | K31: 智识84 | L31: 力量55 | M31: 充能26.7
A32: 纾难护手 | B32: 敏捷86 | D32: 终结技45.0 | E32: 敏捷94 | G32: 终结技49.5 | H32: 敏捷103 | J32: 终结技54.0 | K32: 敏捷111 | M32: 终结技58.5
A33: 纾难手套 | B33: 力量86 | D33: 全技伤24.0 | E33: 力量94 | G33: 全技伤26.4 | H33: 力量103 | J33: 全技伤28.8 | K33: 力量111 | M33: 全技伤31.2

Sheet 配件库
A1: 精锻等级 | B1: 0 | E1: 1 | H1: 2 | K1: 3
A2: 名称 | B2: 词条1 | C2: 词条2 | D2: 词条3 | E2: 词条1 | F2: 词条2 | G2: 词条3 | H2: 词条1 | I2: 词条2 | J2: 词条3 | K2: 词条1 | L2: 词条2 | M2: 词条3
A3: 拓荒增量供氧栓 | B3: 敏捷32 | C3: 智识21 | D3: 副能力20.7 | E3: 敏捷35 | F3: 智识23 | G3: 副能力22.8 | H3: 敏捷38 | I3: 智识25 | J3: 副能力24.8 | K3: 敏捷41 | L3: 智识27 | M3: 副能力26.9
A4: 拓荒增量供氧栓一 | B4: 智识32 | C4: 敏捷21 | D4: 副能力20.7 | E4: 智识35 | F4: 敏捷23 | G4: 副能力22.8 | H4: 智识38 | I4: 敏捷25 | J4: 副能力24.8 | K4: 智识41 | L4: 敏捷27 | M4: 副能力26.9
A5: 拓荒通信器一 | B5: 力量32 | C5: 智识21 | D5: 冰电伤23.0 | E5: 力量35 | F5: 智识23 | G5: 冰电伤25.3 | H5: 力量38 | I5: 智识25 | J5: 冰电伤27.6 | K5: 力量41 | L5: 智识27 | M5: 冰电伤29.9
A6: 拓荒通信器 | B6: 力量32 | C6: 敏捷21 | D6: 连携伤41.4 | E6: 力量35 | F6: 敏捷23 | G6: 连携伤45.5 | H6: 力量38 | I6: 敏捷25 | J6: 连携伤49.7 | K6: 力量41 | L6: 敏捷27 | M6: 连携伤53.8
A7: 拓荒分析仪 | B7: 力量41 | D7: 终结技51.7 | E7: 力量45 | G7: 终结技56.9 | H7: 力量49 | J7: 终结技62.1 | K7: 力量53 | M7: 终结技67.3
A8: 拓荒供氧栓 | B8: 意志41 | D8: 物伤23.0 | E8: 意志45 | G8: 物伤25.3 | H8: 意志49 | J8: 物伤27.6 | K8: 意志53 | M8: 物伤29.9
A9: 应龙短刃 | B9: 意志32 | C9: 敏捷21 | D9: 连携伤41.4 | E9: 意志35 | F9: 敏捷23 | G9: 连携伤45.5 | H9: 意志38 | I9: 敏捷25 | J9: 连携伤49.7 | K9: 意志41 | L9: 敏捷27 | M9: 连携伤53.8
A10: 应龙短刃一 | B10: 智识32 | C10: 力量21 | D10: 全技伤27.6 | E10: 智识35 | F10: 力量23 | G10: 全技伤30.4 | H10: 智识38 | I10: 力量25 | J10: 全技伤33.1 | K10: 智识41 | L10: 力量27 | M10: 全技伤35.9
A11: 应龙雷达 | B11: 力量32 | C11: 意志21 | D11: 物伤23.0 | E11: 力量35 | F11: 意志23 | G11: 物伤25.3 | H11: 力量38 | I11: 意志25 | J11: 物伤27.6 | K11: 力量41 | L11: 意志27 | M11: 物伤29.9
A12: 应龙雷达一 | B12: 敏捷32 | C12: 力量21 | D12: 终结技51.7 | E12: 敏捷35 | F12: 力量23 | G12: 终结技56.9 | H12: 敏捷38 | I12: 力量25 | J12: 终结技62.1 | K12: 敏捷41 | L12: 力量27 | M12: 终结技67.3
A13: 应龙雷达二 | B13: 敏捷32 | C13: 智识21 | D13: 连携伤41.4 | E13: 敏捷35 | F13: 智识23 | G13: 连携伤45.5 | H13: 敏捷38 | I13: 智识25 | J13: 连携伤49.7 | K13: 敏捷41 | L13: 智识27 | M13: 连携伤53.8
A14: 碾骨小雕像 | B14: 意志32 | C14: 敏捷21 | D14: 战技41.4 | E14: 意志35 | F14: 敏捷23 | G14: 战技45.5 | H14: 意志38 | I14: 敏捷25 | J14: 战技49.7 | K14: 意志41 | L14: 敏捷27 | M14: 战技53.8
A15: 碾骨小雕像一 | B15: 意志32 | C15: 智识21 | D15: 连携伤41.4 | E15: 意志35 | F15: 智识23 | G15: 连携伤45.5 | H15: 意志38 | I15: 智识25 | J15: 连携伤49.7 | K15: 意志41 | L15: 智识27 | M15: 连携伤53.8
A16: 碾骨小雕像二 | B16: 意志32 | C16: 智识21 | D16: 战技41.4 | E16: 意志35 | F16: 智识23 | G16: 战技45.5 | H16: 意志38 | I16: 智识25 | J16: 战技49.7 | K16: 意志41 | L16: 智识27 | M16: 战技53.8
A17: 碾骨面具 | B17: 敏捷32 | C17: 力量21 | D17: 失衡伤41.4 | E17: 敏捷35 | F17: 力量23 | G17: 失衡伤45.5 | H17: 敏捷38 | I17: 力量25 | J17: 失衡伤49.7 | K17: 敏捷41 | L17: 力量27 | M17: 失衡伤53.8
A18: 碾骨面具一 | B18: 敏捷32 | C18: 力量21 | D18: 暴击10.3 | E18: 敏捷35 | F18: 力量23 | G18: 暴击11.4 | H18: 敏捷38 | I18: 力量25 | J18: 暴击12.4 | K18: 敏捷41 | L18: 力量27 | M18: 暴击13.5
A19: 碾骨面具二 | B19: 敏捷32 | C19: 力量21 | D19: 战技41.4 | E19: 敏捷35 | F19: 力量23 | G19: 战技45.5 | H19: 敏捷38 | I19: 力量25 | J19: 战技49.7 | K19: 敏捷41 | L19: 力量27 | M19: 战技53.8
A20: 潮涌浊流切割炬 | B20: 智识32 | C20: 力量21 | D20: 普攻27.6 | E20: 智识35 | F20: 力量23 | G20: 普攻30.4 | H20: 智识38 | I20: 力量25 | J20: 普攻33.1 | K20: 智识41 | L20: 力量27 | M20: 普攻35.9
... A32: 动火用储能匣 | B32: 力量32 | C32: 敏捷21 | D32: 技艺41 | E32: 力量35 | F32: 敏捷23 | G32: 技艺45 | H32: 力量38 | I32: 敏捷25 | J32: 技艺49 | K32: 力量41 | L32: 敏捷27 | M32: 技艺53
A33: 动火用测温镜 | B33: 智识41 | D33: 战技41.4 | E33: 智识45 | G33: 战技45.5 | H33: 智识49 | J33: 战技49.7 | K33: 智识53 | M33: 战技53.8
A34: 动火用电力匣 | B34: 意志32 | C34: 智识21 | D34: 技艺41 | E34: 意志35 | F34: 智识23 | G34: 技艺45 | H34: 意志38 | I34: 智识25 | J34: 技艺49 | K34: 意志41 | L34: 智识27 | M34: 技艺53
A35: 生物辅助接驳器 | B35: 力量32 | C35: 意志21 | D35: 全减17.1 | E35: 力量35 | F35: 意志23 | G35: 全减18.5 | H35: 力量38 | I35: 意志25 | J35: 全减19.9 | K35: 力量41 | L35: 意志27 | M35: 全减21.2
A36: 生物辅助护盾针 | B36: 意志41 | D36: 治疗20.7 | E36: 意志45 | G36: 治疗22.8 | H36: 意志49 | J36: 治疗24.8 | K36: 意志53 | M36: 治疗26.9
A37: 生物辅助护板 | B37: 意志32 | C37: 智识21 | D37: 主能力20.7 | E37: 意志35 | F37: 智识23 | G37: 主能力22.8 | H37: 意志38 | I37: 智识25 | J37: 主能力24.8 | K37: 意志41 | L37: 智识27 | M37: 主能力26.9
A38: 生物辅助接驳器一 | B38: 力量32 | C38: 意志21 | D38: 生命41.4 | E38: 力量35 | F38: 意志23 | G38: 生命45.5 | H38: 力量38 | I38: 意志25 | J38: 生命49.7 | K38: 力量41 | L38: 意志27 | M38: 生命53.8
A39: 生物辅助接驳器二 | B39: 力量41 | D39: 生命41.4 | E39: 力量45 | G39: 生命45.5 | H39: 力量49 | J39: 生命49.7 | K39: 力量53 | M39: 生命53.8
A40: 点剑定位信标 | B40: 力量41 | D40: 技艺41 | E40: 力量45 | G40: 技艺45 | H40: 力量49 | J40: 技艺49 | K40: 力量53 | M40: 技艺53
A41: 点剑微型滤芯 | B41: 力量32 | C41: 意志21 | D41: 物伤23.0 | E41: 力量35 | F41: 意志23 | G41: 物伤25.3 | H41: 力量38 | I41: 意志25 | J41: 物伤27.6 | K41: 力量41 | L41: 意志27 | M41: 物伤29.9
A42: 点剑火石 | B42: 敏捷32 | C42: 力量21 | D42: 物伤23.0 | E42: 敏捷35 | F42: 力量23 | G42: 物伤25.3 | H42: 敏捷38 | I42: 力量25 | J42: 物伤27.6 | K42: 敏捷41 | L42: 力量27 | M42: 物伤29.9
A43: 点剑短刃 | B43: 敏捷32 | C43: 力量21 | D43: 终结技51.7 | E43: 敏捷35 | F43: 力量23 | G43: 终结技56.9 | H43: 敏捷38 | I43: 力量25 | J43: 终结技62.1 | K43: 敏捷41 | L43: 力量27 | M43: 终结技67.3
A44: 轻超域腕表 | B44: 力量32 | C44: 敏捷21 | D44: 战技41.4 | E44: 力量35 | F44: 敏捷23 | G44: 战技45.5 | H44: 力量38 | I44: 敏捷25 | J44: 战技49.7 | K44: 力量41 | L44: 敏捷27 | M44: 战技53.8
A45: 轻超域稳定盘一 | B45: 敏捷32 | C45: 力量21 | D45: 物伤23.0 | E45: 敏捷35 | F45: 力量23 | G45: 物伤25.3 | H45: 敏捷38 | I45: 力量25 | J45: 物伤27.6 | K45: 敏捷41 | L45: 力量27 | M45: 物伤29.9
A46: 轻超域分析环 | B46: 力量32 | C46: 意志21 | D46: 物伤23.0 | E46: 力量35 | F46: 意志23 | G46: 物伤25.3 | H46: 力量38 | I46: 意志25 | J46: 物伤27.6 | K46: 力量41 | L46: 意志27 | M46: 物伤29.9
A47: 轻超域稳定盘 | B47: 敏捷32 | C47: 力量21 | D47: 技艺41 | E47: 敏捷35 | F47: 力量23 | G47: 技艺45 | H47: 敏捷38 | I47: 力量25 | J47: 技艺49 | K47: 敏捷41 | L47: 力量27 | M47: 技艺53
A48: 脉冲式侵入核 | B48: 意志41 | D48: 终结技51.7 | E48: 意志45 | G48: 终结技56.9 | H48: 意志49 | J48: 终结技62.1 | K48: 意志53 | M48: 终结技67.3
A49: 脉冲式校准器 | B49: 智识41 | D49: 技艺41 | E49: 智识45 | G49: 技艺45 | H49: 智识49 | J49: 技艺49 | K49: 智识53 | M49: 技艺53
A50: 脉冲式探针 | B50: 智识32 | C50: 敏捷21 | D50: 技艺41 | E50: 智识35 | F50: 敏捷23 | G50: 技艺45 | H50: 智识38 | I50: 敏捷25 | J50: 技艺49 | K50: 智识41 | L50: 敏捷27 | M50: 技艺53
A51: 长息辅助臂 | B51: 意志32 | C51: 智识21 | D51: 充能24.6 | E51: 意志35 | F51: 智识23 | G51: 充能27.1 | H51: 意志38 | I51: 智识25 | J51: 充能29.6 | K51: 意志41 | L51: 智识27 | M51: 充能32.0
...

Sheet 套装效果库
A2: 拓荒 | B2: 连携技冷却缩减+15。装备者通过技能恢复技力后，全队造成的伤害+16%，持续15秒，该效果无法叠加。
A3: 应龙 | B3: 攻击力15。当小队内任意干员施放战技时，装备者获得一层应龙之锐，使得该干员下一次连携技伤害+20%，应龙之锐最多叠加3层
A4: 碾骨 | B4: 攻击力15。当装备者施放连携技时，获得一层碾骨重压，下一次的战技伤害+30%，碾骨重压最多可叠加2层。
A5: 潮涌 | B5: 全技伤20。装备者使敌人达到2层及以上法术附着后，造成的法术伤害+35%，持续15秒，该效果无法叠加。
A6: 清波 | B6: 连携技冷却缩减+15。当装备者施放连携技时，所有技能伤害+20.0%，持续15秒。该效果最多叠加2层，每层单独计算持续时间。
A7: 警用 | B7: 暴击05。当触发暴击后，5秒内+5%攻击力，该效果最多叠加5层。层数叠满后，额外+5%暴击率，该效果无法叠加。
A8: 壤流 | B8: 攻击力10。装备者每次消耗法术异常，根据异常等级获得相同层数的强化状态，每层使自身法术伤害+15%，持续25秒。强化状态最多存在3层，每层单独计算持续时间。
A9: 动火 | B9: 源石技艺30。当装备者施加燃烧后，灼热+伤害+50%，持续10秒，该效果无法叠加；当装备者施加腐蚀后，自然伤害+50%，持续10秒，该效果无法叠加。
A10: 生物 | B10: 治疗效率20。当装备者治疗我方目标后，使该目标在10秒内受到的所有类型伤害-15%；如果该目标受到的治疗量溢出，则受到的所有类型伤害-30%。上述效果无法叠加。
A11: 点剑 | B11: 失衡效率20。当装备者造成物理异常后，额外造成一次250%攻击力的物理伤害[10点失衡值]。该效果每15秒最多触发一次。
A12: 轻超 | B12: 攻击力+8。装备者施加破防后，物理伤害+8%，持续15秒，最多可叠加4层。若使目标达到4层破防，物理伤害额外+16%，持续10秒，该效果无法叠加。
A13: 脉冲 | B13: 源石技艺+30。当装备者施加导电后，电磁伤害+50%，持续10秒，该效果无法叠加；当装备者施加冻结后，寒冷伤害+50%，持续10秒，该效果无法叠加。
A14: 长息 | B14: 生命值+1000。装备者施加增幅、庇护、脆弱、虚弱后，使其他队友造成的伤害+16%，持续15秒。该效果无法叠加。

Sheet 计算器
N2: 热启动爆发轴 | P2: 冲能轴 | Q2: 爆发轴
C20: =SUM(C27:C35) -> 227228.53
C22: =SUM(C32:C33) -> 63101.732
A24: 列1 | B24: 列2 | C24: 列3 | D24: 列4 | E24: 列5 | F24: buff图标 | G24: 列6 | H24: 列7 | I24: 列8 | J24: 列9 | K24: 列10 | L24: 列11 | M24: 列12 | N24: 列13 | O24: 列14 | P24: 列15 | Q24: 列16 | R24: 列17 | S24: 列18 | T24: 列19 | U24: 攻击计算器 | V24: 列20 | W24: 列21 | X24: 列22 | Y24: 列23 | Z24: 面板乘区 | AA24: 列24 | AB24: 列25 | AC24: 列26 | AD24: 伤害加成 | AE24: 列27 | AF24: 列28 | AG24: 列29 | AH24: 列30 | AI24: 列31 | AJ24: 拐 | AK24: 列32 | AL24: 列33 | AM24: 列34 | AN24: 列35 | AO24: 列36 | AP24: 列37 | AQ24: 敌人乘区 | AR24: 列38 | AS24: 列39
A25: 技能名称 | B25: 不暴击伤害 | C25: 暴击期望伤害 | D25: 暴击伤害 | E25: 伤害占比 | F25: 失衡 | G25: 增益2 | H25: 增益3 | I25: 增益4 | J25: 增益5 | K25: 增益6 | L25: 增益7 | M25: 增益8 | N25: 增益9 | O25: 增益10 | P25: 增益11 | Q25: 增益12 | R25: 增益13 | S25: 增益14 | T25: 增益15 | U25: 基础攻击力 | V25: 百分比 | W25: 固定数值 | X25: 能力值加成 | Y25: 即时攻击力 | Z25: 倍率 | AA25: 暴击率 | AB25: 暴击伤害 | AC25: 源石技艺 | AD25: 基础伤害加成 | AE25: 普攻 | AF25: 战技 | AG25: 连携 | AH25: 大招 | AI25: 总伤害加成 | AJ25: 脆弱 | AK25: 增幅 | AL25: 易伤 | AM25: 抗性 | AN25: 连击 | AO25: 失衡易伤 | AP25: 特殊加成 | AQ25: 防御区 | AR25: 各属性抗性区在开发 | AS25: 敌人减伤区
A27: 伊冯重击普攻 | B27: =PRODUCT(Y27:Z27,AC27,AI27:AS27) -> 2986.9812 | C27: =B27*(1+表2_5[[#This Row],[列24]]*(表2_5[[#This Row],[列25]]-1)) -> 3061.6557 | D27: =PRODUCT(Y27:Z27,AB27:AC27,AI27:AS27) -> 4480.4718 | E27: =表2_5[[#This Row],[列3]]/$C$61 -> 0.011141695 | F27: 否 | U27: =IFERROR(VLOOKUP($A27,$A$86:$X$1000,MATCH(U$25,$A$87:$J$87,0), FALSE), 0) * (LEN($A27) > 0) -> 826 | V27: {=IFERROR(VLOOKUP($A27,$A$86:$X$1000,MATCH(V$25,$A$87:$J$87,0), FALSE), 0) * (LEN($A27) > 0)+SUMPRODUCT( IFERROR(VLOOKUP($G27:$T27, $B$87:$X$1000,MATCH(V$25,$B$87:$X$87,0), FALSE), 0) * (LEN($G27:$T27) > 0) )} -> 0 | W27: =IFERROR(VLOOKUP($A27,$A$86:$X$1000,MATCH(W$25,$A$87:$J$87,0), FALSE), 0) * (LEN($A27) > 0) -> 0 | X27: =IFERROR(VLOOKUP($A27,$A$86:$X$1000,MATCH(X$25,$A$87:$J$87,0), FALSE), 0) * (LEN($A27) > 0) -> 4.74 | Y27: =(U27*(1+V27)+W27)*(1+X27) -> 4741.24 | Z27: =IFERROR(VLOOKUP($A27,$A$86:$X$1000,MATCH(Z$25,$A$87:$J$87,0), FALSE), 0) * (LEN($A27) > 0) -> 1.26 | AA27: {=IFERROR(VLOOKUP($A27,$A$86:$X$1000,MATCH(AA$25,$A$87:$J$87,0), FALSE), 0) * (LEN($A27) > 0)+SUMPRODUCT( IFERROR(VLOOKUP($G27:$T27, $B$87:$X$1000,MATCH(AA$25,$B$87:$X$87,0), FALSE), 0) * (LEN($G27:$T27) > 0) )} -> 0.05 | AB27: {=1+SUMPRODUCT( IFERROR(VLOOKUP($G27:$T27, $B$87:$X$1000,MATCH(AB$25,$B$87:$X$87,0), FALSE), 0) * (LEN($G27:$T27) > 0) )+IFERROR(VLOOKUP($A27,$A$87:$X$1000,MATCH(AB$25,$A$87:$J$87,0), FALSE), 0) * (LEN($A27) > 0)} -> 1.5 | AC27: {=1+SUMPRODUCT( IFERROR(VLOOKUP($G27:$T27, $B$87:$X$1000,MATCH(AC$25,$B$87:$X$87,0), FALSE), 0) * (LEN($G27:$T27) > 0) )} -> 1 | AD27: {=SUMPRODUCT( IFERROR(VLOOKUP($G27:$T27, $B$87:$X$1000,MATCH(AD$25,$B$87:$X$87,0), FALSE), 0) * (LEN($G27:$T27) > 0) )+IFERROR(VLOOKUP($A27,$A$88:$X$1000,MATCH(AD$25,$A$87:$X$87,0), FALSE), 0) * (LEN($A27) > 0)} -> 0 | AE27: {=SUMPRODUCT( IFERROR(VLOOKUP($G27:$T27, $B$87:$X$1000,MATCH(AE$25,$B$87:$X$87,0), FALSE), 0) * (LEN($G27:$T27) > 0) )+IFERROR(VLOOKUP($A27,$A$88:$X$1000,MATCH(AE$25,$A$87:$X$87,0), FALSE), 0) * (LEN($A27) > 0)} -> 0 | AF27: {=SUMPRODUCT( IFERROR(VLOOKUP($G27:$T27, $B$87:$X$1000,MATCH(AF$25,$B$87:$X$87,0), FALSE), 0) * (LEN($G27:$T27) > 0) )+IFERROR(VLOOKUP($A27,$A$88:$X$1000,MATCH(AF$25,$A$87:$X$87,0), FALSE), 0) * (LEN($A27) > 0)} -> 0 | AG27: {=SUMPRODUCT( IFERROR(VLOOKUP($G27:$T27, $B$87:$X$1000,MATCH(AG$25,$B$87:$X$87,0), FALSE), 0) * (LEN($G27:$T27) > 0) )+IFERROR(VLOOKUP($A27,$A$88:$X$1000,MATCH(AG$25,$A$87:$X$87,0), FALSE), 0) * (LEN($A27) > 0)} -> 0 | AH27: {=SUMPRODUCT( IFERROR(VLOOKUP($G27:$T27, $B$87:$X$1000,MATCH(AH$25,$B$87:$X$87,0), FALSE), 0) * (LEN($G27:$T27) > 0) )+IFERROR(VLOOKUP($A27,$A$88:$X$1000,MATCH(AH$25,$A$87:$X$87,0), FALSE), 0) * (LEN($A27) > 0)} -> 0 | AI27: =1 + AD27 + IF( LEN($A27) > 0, IFERROR( HLOOKUP(RIGHT($A27,2), $AE$25:$AH$80, ROW()-ROW($AE$25) + 1, FALSE), 0 ), 0 ) -> 1 | AJ27: {=1+SUMPRODUCT( IFERROR(VLOOKUP($G27:$T27, $B$87:$X$1000,MATCH(AJ$25,$B$87:$X$87,0), FALSE), 0) * (LEN($G27:$T27) > 0) )} -> 1 | AK27: {=1+SUMPRODUCT( IFERROR(VLOOKUP($G27:$T27, $B$87:$X$1000,MATCH(AK$25,$B$87:$X$87,0), FALSE), 0) * (LEN($G27:$T27) > 0) )} -> 1 | AL27: {=1+SUMPRODUCT( IFERROR(VLOOKUP($G27:$T27, $B$87:$X$1000,MATCH(AL$25,$B$87:$X$87,0), FALSE), 0) * (LEN($G27:$T27) > 0) )} -> 1 | AM27: {=1+SUMPRODUCT( IFERROR(VLOOKUP($G27:$T27, $B$87:$X$1000,MATCH(AM$25,$B$87:$X$87,0), FALSE), 0) * (LEN($G27:$T27) > 0) )} -> 1 | AN27: {=1+SUMPRODUCT( IFERROR(VLOOKUP($G27:$T27, $B$87:$X$1000,MATCH(AN$25,$B$87:$X$87,0), FALSE), 0) * (LEN($G27:$T27) > 0) )} -> 1 | AO27: =IF($F27="是",1.3,1) -> 1 | AQ27: =0.5 -> 0.5
